Workbook

Sheet Balance Sheet
A1: Ajanta Pharma Limited — Consolidated Balance Sheet
A2: As at 31 March 2026 (₹ in crore)
A4: Particulars | B4: Note | C4: 31-Mar-2026 | D4: 31-Mar-2025 | E4: 31-Mar-2024 | F4: 31-Mar-2023
A5: ASSETS
A6: Non-Current Assets
A7: Property, Plant and Equipment | B7: 8 | C7: 1726.35 | D7: 1624.87 | E7: 1384.13 | F7: 1407.83
A8: Capital Work-in-Progress | B8: 8 | C8: 258.05 | D8: 176.27 | E8: 256.45 | F8: 209.47
A9: Right-of-Use Assets | B9: 8 | C9: 99.02 | D9: 90.63 | E9: 80.4 | F9: 80.86
A10: Other Intangible Assets | B10: 8 | C10: 41.58 | D10: 46.52 | E10: 14.66 | F10: 7.75
A11: Investments (Non-Current) | B11: 9 | C11: 28.5 | D11: 25.24 | E11: 18.58 | F11: 25.1
A12: Other Non-Current Financial Assets | B12: 10 | C12: 7.99 | D12: 9.25 | E12: 9.36 | F12: 11.09
A13: Deferred Tax Assets (Net) | B13: 11 | C13: 188.59 | D13: 186.43 | E13: 134.45 | F13: 96.77
A14: Income Tax Assets (Net) | B14: 12 | C14: 7.56 | D14: 0 | E14: 0 | F14: 0.83
A15: Other Non-Current Assets | B15: 13 | C15: 61.77 | D15: 12.71 | E15: 9.44 | F15: 5.32
A16: Total Non-Current Assets | C16: =SUM(C7:C15) -> 2419.41 | D16: =SUM(D7:D15) -> 2171.92 | E16: =SUM(E7:E15) -> 1907.47 | F16: =SUM(F7:F15) -> 1845.02
A18: Current Assets
A19: Inventories | B19: 14 | C19: 938.54 | D19: 903.85 | E19: 828.36 | F19: 815.63
A20: Investments (Current) | B20: 15 | C20: 559.85 | D20: 438.71 | E20: 330.05 | F20: 510.27
A21: Trade Receivables | B21: 16 | C21: 1853.88 | D21: 1182.74 | E21: 1246.84 | F21: 1056.9
A22: Cash and Cash Equivalents | B22: 17 | C22: 103.26 | D22: 175.12 | E22: 129.49 | F22: 329.83
A23: Bank Balances other than Cash Equiv. | B23: 18 | C23: 1.51 | D23: 1.12 | E23: 1.28 | F23: 1.07
A24: Loans (Current) | B24: 19 | C24: 1.68 | D24: 2.54 | E24: 33.96 | F24: 17.39
A25: Other Financial Assets (Current) | B25: 20 | C25: 8.98 | D25: 2.32 | E25: 19.02 | F25: 2.48
A26: Other Current Assets | B26: 21 | C26: 267.73 | D26: 123.3 | E26: 133.07 | F26: 91.61
A27: Assets Classified as Held for Sale | B27: 22 | C27: 0 | D27: 13.33 | E27: 8.85 | F27: 8.82
A28: Total Current Assets | C28: =SUM(C19:C27) -> 3735.43 | D28: =SUM(D19:D27) -> 2843.03 | E28: =SUM(E19:E27) -> 2730.92 | F28: =SUM(F19:F27) -> 2834
A30: TOTAL ASSETS | C30: =C16+C28 -> 6154.84 | D30: =D16+D28 -> 5014.95 | E30: =E16+E28 -> 4638.39 | F30: =F16+F28 -> 4679.02
A32: EQUITY AND LIABILITIES
A33: Equity
A34: Equity Share Capital | B34: 23 | C34: 25.07 | D34: 25.07 | E34: 25.27 | F34: 25.27
A35: Other Equity | B35: 24 | C35: 4502.02 | D35: 3765.22 | E35: 3542.09 | F35: 3362.72
A36: Total Equity | C36: =SUM(C34:C35) -> 4527.09 | D36: =SUM(D34:D35) -> 3790.29 | E36: =SUM(E34:E35) -> 3567.36 | F36: =SUM(F34:F35) -> 3387.99
A38: Non-Current Liabilities
A39: Borrowings (Non-Current) | B39: 25 | C39: 0 | D39: 0 | E39: 0 | F39: 1.25
A40: Lease Liabilities (Non-Current) | B40: 25 | C40: 39.42 | D40: 34.72 | E40: 23.52 | F40: 24.95
A41: Other Financial Liabilities (Non-Current) | B41: 26 | C41: 1.82 | D41: 1.05 | E41: 1.37 | F41: 1.01
A42: Other Non-Current Liabilities | B42: 27 | C42: 1.67 | D42: 2 | E42: 2.34 | F42: 2.67
A43: Provisions (Non-Current) | B43: 28 | C43: 51.15 | D43: 80.27 | E43: 39.54 | F43: 24.15
A44: Deferred Tax Liabilities (Net) | B44: 29 | C44: 117.94 | D44: 110.52 | E44: 108.5 | F44: 97.72
A45: Total Non-Current Liabilities | C45: =SUM(C39:C44) -> 212 | D45: =SUM(D39:D44) -> 228.56 | E45: =SUM(E39:E44) -> 175.27 | F45: =SUM(F39:F44) -> 151.75
...

Sheet Profit & Loss
A1: Ajanta Pharma Limited — Consolidated Statement of Profit and Loss
A2: (₹ in crore)
A4: Particulars | B4: Note | C4: FY26 | D4: FY25 | E4: FY24 | F4: FY23
A5: Income
A6: Revenue from Operations | B6: 37 | C6: 5452.86 | D6: 4648.1 | E6: 4208.71 | F6: 3742.64
A7: Other Income | B7: 38 | C7: 172.07 | D7: 94.5 | E7: 84.6 | F7: 98.64
A8: Total Income | C8: =C6+C7 -> 5624.93 | D8: =D6+D7 -> 4742.6 | E8: =E6+E7 -> 4293.31 | F8: =F6+F7 -> 3841.28
A10: Expenses
A11: Cost of Materials Consumed | B11: 39 | C11: 916.51 | D11: 846.6 | E11: 939.43 | F11: 878.36
A12: Purchase of Stock-in-Trade | B12: 40 | C12: 229.79 | D12: 249.8 | E12: 166.35 | F12: 146.28
A13: Changes in Inventories | B13: 41 | C13: 37.46 | D13: -25.64 | E13: -39.21 | F13: 25.76
A14: Employee Benefits Expense | B14: 42 | C14: 1291.15 | D14: 1089.69 | E14: 900.34 | F14: 785.14
A15: Finance Costs | B15: 43 | C15: 16.11 | D15: 20.73 | E15: 7.21 | F15: 5.84
A16: Depreciation and Amortisation | B16: 44 | C16: 173.14 | D16: 144.11 | E16: 135.4 | F16: 130.8
A17: Other Expenses | B17: 45 | C17: 1583.12 | D17: 1228.15 | E17: 1069.86 | F17: 1123.85
A18: Total Expenses | C18: =SUM(C11:C17) -> 4247.28 | D18: =SUM(D11:D17) -> 3553.44 | E18: =SUM(E11:E17) -> 3179.38 | F18: =SUM(F11:F17) -> 3096.03
A20: Profit Before Tax | C20: =C8-C18 -> 1377.65 | D20: =D8-D18 -> 1189.16 | E20: =E8-E18 -> 1113.93 | F20: =F8-F18 -> 745.25
A21: Tax Expense | B21: 64
A22: Current Tax (for current year) | C22: 300.17 | D22: 337.28 | E22: 298.22 | F22: 175.58
A23: Current Tax (for earlier years) | C23: -0.09 | D23: -24.98 | E23: 23.84 | F23: 21.66
A24: Deferred Tax | C24: 21.57 | D24: -43.53 | E24: -24.3 | F24: -39.97
A25: Total Tax Expense | C25: =SUM(C22:C24) -> 321.65 | D25: =SUM(D22:D24) -> 268.77 | E25: =SUM(E22:E24) -> 297.76 | F25: =SUM(F22:F24) -> 157.27
A26: Profit for the Year | C26: =C20-C25 -> 1056 | D26: =D20-D25 -> 920.39 | E26: =E20-E25 -> 816.17 | F26: =F20-F25 -> 587.98
A28: Other Comprehensive Income
A29: Remeasurement of Defined Benefit Liability/(Asset) | C29: -0.48 | D29: -8.96 | E29: -3.88 | F29: -3.49
A30: Income Tax on above | C30: 0.17 | D30: 3.13 | E30: 1.36 | F30: 1.22
A31: Net OCI (not reclassified) | C31: =C29+C30 -> -0.31 | D31: =D29+D30 -> -5.83 | E31: =E29+E30 -> -2.52 | F31: =F29+F30 -> -2.27
A32: FX Translation - Foreign Operations | C32: 29.39 | D32: 7.68 | E32: 3.33 | F32: 17.12
A33: Income Tax on above | C33: 0 | D33: 0 | E33: 0 | F33: 0
A34: Net OCI (reclassified) | C34: =C32+C33 -> 29.39 | D34: =D32+D33 -> 7.68 | E34: =E32+E33 -> 3.33 | F34: =F32+F33 -> 17.12
A35: Total OCI for the Year | C35: =C31+C34 -> 29.08 | D35: =D31+D34 -> 1.85 | E35: =E31+E34 -> 0.81 | F35: =F31+F34 -> 14.85
A36: Total Comprehensive Income | C36: =C26+C35 -> 1085.08 | D36: =D26+D35 -> 922.24 | E36: =E26+E35 -> 816.98 | F36: =F26+F35 -> 602.83

Sheet Cash Flow Statement
A1: Ajanta Pharma Limited — Consolidated Statement of Cash Flow
A2: (₹ in crore) — working capital lines aligned across years; FY26/25 use aggregated source categories, FY24/23 use granular source categories grouped to match
A4: Particulars | B4: FY26 | C4: FY25 | D4: FY24 | E4: FY23
A5: A. Cash Flow from Operating Activities
A6: Profit Before Tax | B6: 1377.65 | C6: 1189.16 | D6: 1113.93 | E6: 745.25
A7: Add: Depreciation and Amortisation | B7: 173.14 | C7: 144.11 | D7: 135.4 | E7: 130.8
A8: Add: Finance Costs | B8: 16.11 | C8: 20.73 | D8: 7.21 | E8: 5.84
A9: Other Non-Cash/Non-Operating Adjustments (net) | B9: -25.79 | C9: -52.73 | D9: -59.58 | E9: -5.34
A10: Operating Cash Flow before Working Capital Changes | B10: =SUM(B6:B9) -> 1541.11 | C10: =SUM(C6:C9) -> 1301.27 | D10: =SUM(D6:D9) -> 1196.96 | E10: =SUM(E6:E9) -> 876.55
A11: (Increase)/Decrease in Trade Receivables | B11: -590.84 | C11: 80.48 | D11: -178.88 | E11: -10.55
A12: (Increase)/Decrease in Other Receivables/Assets (net) | B12: -158.82 | C12: 25.29 | D12: -39.39 | E12: 29.47
A13: (Increase) in Inventories | B13: -30.95 | C13: -74.51 | D13: -12.3 | E13: -22.37
A14: Increase/(Decrease) in Trade Payables | B14: 90.79 | C14: -8.45 | D14: 40.85 | E14: 96.91
A15: Increase in Other Payables/Liabilities (net) | B15: 59.28 | C15: 115.64 | D15: 73.35 | E15: -32.39
A16: Increase/(Decrease) in Provisions | B16: -22.39 | C16: 40.48 | D16: 16.61 | E16: 5.77
A17: Cash Generated from Operating Activities | B17: =B10+SUM(B11:B16) -> 888.18 | C17: =C10+SUM(C11:C16) -> 1480.2 | D17: =D10+SUM(D11:D16) -> 1097.2 | E17: =E10+SUM(E11:E16) -> 943.39
A18: Less: Net Income Tax Paid | B18: -358.99 | C18: -322.97 | D18: -312.13 | E18: -151.29
A19: Net Cash from Operating Activities | B19: =B17+B18 -> 529.19 | C19: =C17+C18 -> 1157.23 | D19: =D17+D18 -> 785.07 | E19: =E17+E18 -> 792.1
A21: B. Cash Flow from Investing Activities
A22: Capital Expenditure (PP&E + Intangibles) | B22: -365.16 | C22: -317.92 | D22: -152.41 | E22: -174.49
A23: Proceeds from Sale of PP&E | B23: 5.41 | C23: 1.14 | D23: 13.38 | E23: 0.73
A24: Other Investing Adjustments (net) | B24: -0.39 | C24: 0.16 | D24: -0.21 | E24: 4.35
A25: Purchase of Current Investments | B25: -2659.98 | C25: -2761.21 | D25: -2079.76 | E25: -1666.86
A26: Proceeds from Sale of Current Investments | B26: 2549.09 | C26: 2663.48 | D26: 2257.39 | E26: 1276.15
A27: Income on Investments and Deposits | B27: 45.37 | C27: 44.08 | D27: 27 | E27: 0.52
A28: Investment in LLP / Non-Current Investment | B28: -3.26 | C28: -6.25 | D28: 0 | E28: 0
A29: Net Cash used in Investing Activities | B29: =SUM(B22:B28) -> -428.92 | C29: =SUM(C22:C28) -> -376.52 | D29: =SUM(D22:D28) -> 65.39 | E29: =SUM(E22:E28) -> -559.6
A31: C. Cash Flow from Financing Activities
A32: Proceeds from Issue of Equity Shares | B32: 0 | C32: 0.01 | D32: 0 | E32: 0
A33: Proceeds/(Repayment) of Borrowings (net) | B33: 209.4 | C33: 1.1 | D33: 0.06 | E33: -0.49
A34: Interest Paid | B34: -12.8 | C34: -17.31 | D34: -3.53 | E34: -2.33
A35: Payment of Lease Liability | B35: -14.8 | C35: -14.89 | D35: -16.23 | E35: -14.25
A36: Payment for Buyback of Equity Shares (incl. expenses) | B36: 0 | C36: -352.95 | D36: -389.19 | E36: -1.44
A37: Dividend Paid | B37: -349.72 | C37: -349.37 | D37: -642.17 | E37: -89.69
A38: Net Cash used in Financing Activities | B38: =SUM(B32:B37) -> -167.92 | C38: =SUM(C32:C37) -> -733.41 | D38: =SUM(D32:D37) -> -1051.06 | E38: =SUM(E32:E37) -> -108.2
A40: Net Increase/(Decrease) in Cash and Cash Equivalents | B40: =B19+B29+B38 -> -67.65 | C40: =C19+C29+C38 -> 47.3 | D40: =D19+D29+D38 -> -200.6 | E40: =E19+E29+E38 -> 124.3
A41: Opening Balance of Cash and Cash Equivalents | B41: 175.12 | C41: 129.49 | D41: 329.83 | E41: 206.36
A42: Closing Balance of Cash and Cash Equivalents | B42: =B40+B41 -> 107.47 | C42: =C40+C41 -> 176.79 | D42: =D40+D41 -> 129.23 | E42: =E40+E41 -> 330.66

Sheet Transaction Assumptions
A1: Ajanta Pharma Limited — LBO Transaction Assumptions
A2: (₹ in crore unless stated)
A4: Deal Terms
A6: Entry EV/EBITDA Multiple | B6: 9
A7: Exit EV/EBITDA Multiple | B7: 9
A8: Holding Period (years) | B8: 5
A9: Transaction Fees (% of EV) | B9: 0.02
A12: Leverage & Debt Terms
A14: Entry Leverage (Debt / EBITDA, turns) | B14: 7
A15: Term Loan Interest Rate | B15: 0.1
A16: Mandatory Amortization (% of original principal / year) | B16: 0.07
A17: Cash Sweep % (of excess FCF beyond mandatory amort) | B17: 1
A20: FY26A Anchor Financials (from historicals)
A22: FY26A Revenue | B22: ='Profit & Loss'!C6 -> 5452.86
A23: FY26A EBITDA (EBIT + D&A) | B23: ='Profit & Loss'!C20+'Profit & Loss'!C15+'Profit & Loss'!C16 -> 1566.9
A24: Note: EBITDA is computed as PBT + Finance Costs + D&A, as Ajanta reports Finance Costs within pre-tax profit.
A25: FY26A Total Debt (Non-Current + Current Borrowings) | B25: ='Balance Sheet'!C39+'Balance Sheet'!C48 -> 211.99
A26: FY26A Cash and Cash Equivalents | B26: ='Balance Sheet'!C22 -> 103.26
A28: Implied Entry Valuation (once multiple is set)
A29: Entry Enterprise Value (EV) = FY26A EBITDA x Entry Multiple | B29: =B23*B6 -> 14102.1
A30: Less: Existing Net Debt (Total Debt - Cash) | B30: =-(B25-B26) -> -108.73
A31: Implied Equity Purchase Price | B31: =B29+B30 -> 13993.37
A33: NOTE ON ENTRY MULTIPLE ASSUMPTION
A34: Ajanta Pharma currently trades at ~24-26x EV/EBITDA (per stockanalysis.com, valueinvesting.io, topstockresearch.com, June 2026), reflecting its premium growth and quality profile.
A35: The 9x entry multiple used in this model is a deliberately conservative, illustrative assumption -- NOT a claim that Ajanta is actually available at this price.
A36: This choice was made to construct a realistic, debt-capacity-supportable LBO structure (76% debt / 24% equity at 7x leverage) for the purpose of demonstrating LBO mechanics: Sources & Uses, debt paydown, cash sweep, and returns calculation.
A37: A real-world buyout of Ajanta at its actual trading multiple would require either a much larger equity check (~78% equity at 18x) or unrealistic leverage (10x+) to remain debt-heavy -- illustrating why premium, high-growth public companies are less common LBO targets than stable, lower-multiple cash generators.

Sheet Sources & Uses
A1: Ajanta Pharma Limited — Sources & Uses
A2: (₹ in crore) — at transaction close
A4: USES
A6: Equity Purchase Price | B6: ='Transaction Assumptions'!B31 -> 13993.37
A7: Note: Existing debt is not shown as a separate use — it is already netted into the Equity Purchase Price (Entry EV less net existing debt). | B7: 0
A8: Transaction Fees | B8: ='Transaction Assumptions'!B29*'Transaction Assumptions'!B9 -> 282.042
A9: Total Uses | B9: =SUM(B6:B8) -> 14275.412
A11: SOURCES
A13: New Term Loan (sized off leverage assumption) | B13: ='Transaction Assumptions'!B14*'Transaction Assumptions'!B23 -> 10968.3
A14: Sponsor Equity (plug) | B14: =B9-B13 -> 3307.112
A15: Total Sources | B15: =SUM(B13:B14) -> 14275.412
A17: Check: Total Sources = Total Uses | B17: =B15-B9 -> 0
A19: Memo
A20: Entry Leverage actually achieved (New Debt / FY26A EBITDA) | B20: =B13/'Transaction Assumptions'!B23 -> 7
A21: Equity as % of Total Sources | B21: =B14/B15 -> 0.23166491
A22: Resulting Debt / Equity Ratio (output, not an input) | B22: =B13/B14 -> 3.3165795
A23: Debt as % of Total Sources | B23: =B13/B15 -> 0.76833509
A24: Equity as % of Total Sources (already shown above as B21, repeated for clarity) | B24: =B14/B15 -> 0.23166491

Sheet Opening Pro Forma BS
A1: Ajanta Pharma Limited — Opening Pro Forma Balance Sheet (Post-Transaction)
A2: (₹ in crore) — at transaction close, Day 1
A4: Particulars | B4: FY26A (Pre-Deal) | C4: Adjustments | D4: Pro Forma (Post-Deal)
A6: ASSETS
A7: Non-Current Assets (excl. Goodwill, unchanged from FY26A) | B7: ='Balance Sheet'!C16 -> 2419.41 | C7: =D7-B7 -> 0 | D7: =B7 -> 2419.41
A8: Goodwill (new, created at transaction — plug) | B8: 0 | C8: =D8-B8 -> 9357.55 | D8: ='Transaction Assumptions'!B31-(D7+D12-D25-D28) -> 9357.55
A9: Note: Goodwill is the excess of Equity Purchase Price over net identifiable assets acquired.
A10: Total Non-Current Assets (Pro Forma) | B10: =B7+B8 -> 2419.41 | C10: =D10-B10 -> 9357.55 | D10: =D7+D8 -> 11776.96
A12: Current Assets (unchanged from FY26A, excl. Cash) | B12: ='Balance Sheet'!C28-'Balance Sheet'!C22 -> 3632.17 | C12: =D12-B12 -> 0 | D12: =B12 -> 3632.17
A13: Cash and Cash Equivalents (Day 1 — swept at close, standard cash-free/debt-free LBO convention) | B13: ='Balance Sheet'!C22 -> 103.26 | C13: =D13-B13 -> -103.26 | D13: 0
A14: Note: Under the cash-free/debt-free convention, the target's existing cash is retained by the seller at close; the buyer begins Day 1 with zero cash.
A15: Total Current Assets (Pro Forma) | B15: =B12+B13 -> 3735.43 | C15: =D15-B15 -> -103.26 | D15: =D12+D13 -> 3632.17
A17: TOTAL ASSETS (Pro Forma) | B17: =B10+B15 -> 6154.84 | C17: =D17-B17 -> 9254.29 | D17: =D10+D15 -> 15409.13
A19: EQUITY AND LIABILITIES
A20: Equity (Old equity wiped; New Sponsor Equity Contributed per Sources & Uses) | B20: ='Balance Sheet'!C34+'Balance Sheet'!C35 -> 4527.09 | C20: =D20-B20 -> -1219.978 | D20: ='Sources & Uses'!B14 -> 3307.112
A21: Less: Transaction Fees Expensed at Close | B21: 0 | C21: =D21-B21 -> -282.042 | D21: =-'Sources & Uses'!B8 -> -282.042
A22: Opening Equity (Pro Forma, net of fees) | B22: =B20+B21 -> 4527.09 | C22: =D22-B22 -> -1502.02 | D22: =D20+D21 -> 3025.07
A23: Non-Current Liabilities
A24: Borrowings (Old Non-Current Borrowings wiped; New Term Loan per Sources & Uses) | B24: ='Balance Sheet'!C39 -> 0 | C24: =D24-B24 -> 10968.3 | D24: ='Sources & Uses'!B13 -> 10968.3
A25: Other Non-Current Liabilities (unchanged, excl. old Borrowings) | B25: ='Balance Sheet'!C45-'Balance Sheet'!C39 -> 212 | C25: =D25-B25 -> 0 | D25: =B25 -> 212
A26: Total Non-Current Liabilities (Pro Forma) | B26: =B24+B25 -> 212 | C26: =D26-B26 -> 10968.3 | D26: =D24+D25 -> 11180.3
A28: Current Liabilities (Old Current Borrowings repaid at close; Other Current Liabilities unchanged) | B28: ='Balance Sheet'!C56 -> 1415.75 | C28: =D28-B28 -> -211.99 | D28: ='Balance Sheet'!C56-'Balance Sheet'!C48 -> 1203.76
A29: Note: The target's pre-deal current borrowings are repaid at close and do not carry into the pro forma balance sheet.
A30: Total Liabilities (Pro Forma) | B30: =B26+B28 -> 1627.75 | C30: =D30-B30 -> 10756.31 | D30: =D26+D28 -> 12384.06
A32: TOTAL EQUITY AND LIABILITIES (Pro Forma) | B32: =B22+B30 -> 6154.84 | C32: =D32-B32 -> 9254.29 | D32: =D22+D30 -> 15409.13
A34: Balance Check (Total Assets - Total Equity & Liabilities) | D34: =D17-D32 -> 0

Sheet Operating Model
A1: Ajanta Pharma LBO — Operating Model (Holding Period Projections)
A2: (₹ in crore) — Year 0 = FY26A anchor; Years 1-5 = holding period
A4: Particulars | B4: Year 0 (FY26A) | C4: Year 1 | D4: Year 2 | E4: Year 3 | F4: Year 4 | G4: Year 5 (Exit)
A6: Assumptions
A7: Revenue Growth % | C7: 0.12 | D7: 0.11 | E7: 0.1 | F7: 0.09 | G7: 0.08
A8: EBITDA Margin % | C8: 0.29 | D8: 0.29 | E8: 0.29 | F8: 0.29 | G8: 0.29
A9: D&A % Revenue | C9: 0.0318 | D9: 0.0318 | E9: 0.0318 | F9: 0.0318 | G9: 0.0318
A10: Tax Rate | C10: 0.231 | D10: 0.231 | E10: 0.231 | F10: 0.231 | G10: 0.231
A11: Capex % Revenue | C11: 0.067 | D11: 0.067 | E11: 0.067 | F11: 0.067 | G11: 0.067
A13: Income Statement
A14: Revenue | B14: ='Profit & Loss'!C6 -> 5452.86 | C14: =B14*(1+C7) -> 6107.2032 | D14: =C14*(1+D7) -> 6778.9956 | E14: =D14*(1+E7) -> 7456.8951 | F14: =E14*(1+F7) -> 8128.0157 | G14: =F14*(1+G7) -> 8778.2569
A15: EBITDA | B15: ='Transaction Assumptions'!B23 -> 1566.9 | C15: =C14*C8 -> 1771.0889 | D15: =D14*D8 -> 1965.9087 | E15: =E14*E8 -> 2162.4996 | F15: =F14*F8 -> 2357.1245 | G15: =G14*G8 -> 2545.6945
A16: Less: D&A | B16: =-'Profit & Loss'!C16 -> -173.14 | C16: =-C14*C9 -> -194.20906 | D16: =-D14*D9 -> -215.57206 | E16: =-E14*E9 -> -237.12926 | F16: =-F14*F9 -> -258.4709 | G16: =-G14*G9 -> -279.14857
A17: EBIT | B17: =B15+B16 -> 1393.76 | C17: =C15+C16 -> 1576.8799 | D17: =D15+D16 -> 1750.3367 | E17: =E15+E16 -> 1925.3703 | F17: =F15+F16 -> 2098.6536 | G17: =G15+G16 -> 2266.5459
A18: Less: Interest Expense [Debt Schedule] | B18: =-'Profit & Loss'!C15 -> -16.11 | C18: ='Debt Schedule'!C11 -> -1058.4409 | D18: ='Debt Schedule'!D11 -> -981.66285 | E18: ='Debt Schedule'!E11 -> -904.88475 | F18: ='Debt Schedule'!F11 -> -828.10665 | G18: ='Debt Schedule'!G11 -> -746.73043
A19: EBT (Earnings Before Tax) | B19: =B17+B18 -> 1377.65 | C19: =C17+C18 -> 518.43892 | D19: =D17+D18 -> 768.6738 | E19: =E17+E18 -> 1020.4856 | F19: =F17+F18 -> 1270.547 | G19: =G17+G18 -> 1519.8155
A20: Less: Tax | B20: =-('Profit & Loss'!C22+'Profit & Loss'!C23+'Profit & Loss'!C24) -> -321.65 | C20: =-C19*C10 -> -119.75939 | D20: =-D19*D10 -> -177.56365 | E20: =-E19*E10 -> -235.73217 | F20: =-F19*F10 -> -293.49636 | G20: =-G19*G10 -> -351.07738
A21: Net Income | B21: =B19+B20 -> 1056 | C21: =C19+C20 -> 398.67953 | D21: =D19+D20 -> 591.11015 | E21: =E19+E20 -> 784.7534 | F21: =F19+F20 -> 977.05064 | G21: =G19+G20 -> 1168.7381
A23: Free Cash Flow for Debt Paydown
A24: EBITDA | B24: =B15 -> 1566.9 | C24: =C15 -> 1771.0889 | D24: =D15 -> 1965.9087 | E24: =E15 -> 2162.4996 | F24: =F15 -> 2357.1245 | G24: =G15 -> 2545.6945
A25: Less: Cash Interest Paid [Debt Schedule] | B25: =B18 -> -16.11 | C25: ='Debt Schedule'!C11 -> -1058.4409 | D25: ='Debt Schedule'!D11 -> -981.66285 | E25: ='Debt Schedule'!E11 -> -904.88475 | F25: ='Debt Schedule'!F11 -> -828.10665 | G25: ='Debt Schedule'!G11 -> -746.73043
A26: Less: Cash Taxes | B26: =B20 -> -321.65 | C26: =C20 -> -119.75939 | D26: =D20 -> -177.56365 | E26: =E20 -> -235.73217 | F26: =F20 -> -293.49636 | G26: =G20 -> -351.07738
A27: Less: Capex | B27: =-'Cash Flow Statement'!B22 -> 365.16 | C27: =-C14*C11 -> -409.18261 | D27: =-D14*D11 -> -454.1927 | E27: =-E14*E11 -> -499.61197 | F27: =-F14*F11 -> -544.57705 | G27: =-G14*G11 -> -588.14321
A28: Less: Increase in Net Working Capital (simplified) | B28: 0 | C28: 0 | D28: 0 | E28: 0 | F28: 0 | G28: 0
A29: Free Cash Flow | B29: =SUM(B24:B28) -> 1594.3 | C29: =SUM(C24:C28) -> 183.70597 | D29: =SUM(D24:D28) -> 352.48951 | E29: =SUM(E24:E28) -> 522.27069 | F29: =SUM(F24:F28) -> 690.94449 | G29: =SUM(G24:G28) -> 859.74348

Sheet Debt Schedule
A1: Ajanta Pharma LBO — Debt Schedule
A3: Particulars | B3: Year 0 (Day 1) | C3: Year 1 | D3: Year 2 | E3: Year 3 | F3: Year 4 | G3: Year 5
A5: Term Loan
A6: Opening Balance | B6: ='Sources & Uses'!B13 -> 10968.3 | C6: =B9 -> 10968.3 | D6: =C9 -> 10200.519 | E6: =D9 -> 9432.738 | F6: =E9 -> 8664.957 | G6: =F9 -> 7897.176
A7: Less: Mandatory Amortization | C7: =-'Sources & Uses'!$B$13*'Transaction Assumptions'!$B$16 -> -767.781 | D7: =-'Sources & Uses'!$B$13*'Transaction Assumptions'!$B$16 -> -767.781 | E7: =-'Sources & Uses'!$B$13*'Transaction Assumptions'!$B$16 -> -767.781 | F7: =-'Sources & Uses'!$B$13*'Transaction Assumptions'!$B$16 -> -767.781 | G7: =-'Sources & Uses'!$B$13*'Transaction Assumptions'!$B$16 -> -767.781
A8: Less: Cash Sweep (excess FCF after mandatory amort) | C8: =-MAX(0,MIN(('Operating Model'!C29+C7)*'Transaction Assumptions'!$B$17,C6+C7)) -> 0 | D8: =-MAX(0,MIN(('Operating Model'!D29+D7)*'Transaction Assumptions'!$B$17,D6+D7)) -> 0 | E8: =-MAX(0,MIN(('Operating Model'!E29+E7)*'Transaction Assumptions'!$B$17,E6+E7)) -> 0 | F8: =-MAX(0,MIN(('Operating Model'!F29+F7)*'Transaction Assumptions'!$B$17,F6+F7)) -> 0 | G8: =-MAX(0,MIN(('Operating Model'!G29+G7)*'Transaction Assumptions'!$B$17,G6+G7)) -> -91.962484
A9: Closing Balance | B9: ='Sources & Uses'!B13 -> 10968.3 | C9: =MAX(0,C6+C7+C8) -> 10200.519 | D9: =MAX(0,D6+D7+D8) -> 9432.738 | E9: =MAX(0,E6+E7+E8) -> 8664.957 | F9: =MAX(0,F6+F7+F8) -> 7897.176 | G9: =MAX(0,G6+G7+G8) -> 7037.4325
A10: Average Balance (for interest calculation) | B10: =B9 -> 10968.3 | C10: =(B9+C9)/2 -> 10584.409 | D10: =(C9+D9)/2 -> 9816.6285 | E10: =(D9+E9)/2 -> 9048.8475 | F10: =(E9+F9)/2 -> 8281.0665 | G10: =(F9+G9)/2 -> 7467.3043
A11: Interest Expense | B11: 0 | C11: =-C10*'Transaction Assumptions'!$B$15 -> -1058.4409 | D11: =-D10*'Transaction Assumptions'!$B$15 -> -981.66285 | E11: =-E10*'Transaction Assumptions'!$B$15 -> -904.88475 | F11: =-F10*'Transaction Assumptions'!$B$15 -> -828.10665 | G11: =-G10*'Transaction Assumptions'!$B$15 -> -746.73043

Sheet Returns & Exit
A1: Ajanta Pharma LBO — Returns & Exit Analysis
A2: (₹ in crore)
A4: Exit Valuation
A5: Exit Year EBITDA (Year 5) | B5: ='Operating Model'!G15 -> 2545.6945
A6: Exit EV/EBITDA Multiple | B6: ='Transaction Assumptions'!B7 -> 9
A7: Exit Enterprise Value | B7: =B5*B6 -> 22911.251
A9: Bridge to Equity Value
A10: Exit Enterprise Value | B10: =B7 -> 22911.251
A11: Less: Remaining Debt (Year 5 Closing Balance) | B11: =-'Debt Schedule'!G9 -> -7037.4325
A12: Add: Cash (Year 5 — simplified, held at 0 per cash sweep policy) | B12: 0
A13: Exit Equity Value | B13: =SUM(B10:B12) -> 15873.818
A15: Returns to Sponsor
A16: Sponsor Equity Invested (Year 0, net of fees — positive = cash in) | B16: ='Opening Pro Forma BS'!D22 -> 3025.07
A17: Exit Equity Value (Year 5) | B17: =B13 -> 15873.818
A18: Holding Period (years) | B18: ='Transaction Assumptions'!B8 -> 5
A20: MOIC (Multiple on Invested Capital) | B20: =B17/B16 -> 5.2474217
A21: IRR (Internal Rate of Return) | B21: =(B17/B16)^(1/B18)-1 -> 0.39312214
A23: Note: IRR is computed on a single entry outflow and single exit inflow over the holding period (no interim distributions modeled).

Sheet Sensitivity
A1: Ajanta Pharma LBO — Sensitivity Analysis
A2: Returns across key deal assumptions. Base case (9.0x entry / 9.0x exit / 7.0x leverage) highlighted.
A4: Table 1 — IRR Sensitivity: Entry Multiple (rows) vs. Exit Multiple (columns)
B5: Entry ↓ / Exit → | C5: 8.0x | D5: 9.0x | E5: 10.0x | F5: 11.0x | G5: 12.0x
B6: 8.0x | C6: 0.55665424 | D6: 0.61203563 | E6: 0.66071071 | F6: 0.70426919 | G6: 0.74378211
B7: 9.0x | C7: 0.34526147 | D7: 0.39312211 | E7: 0.43518713 | F7: 0.47283039 | G7: 0.50697749
B8: 10.0x | C8: 0.237525 | D8: 0.28155267 | E8: 0.32024888 | F8: 0.35487745 | G8: 0.38628984
B9: 11.0x | C9: 0.16695358 | D9: 0.20847052 | E9: 0.24496004 | F9: 0.27761386 | G9: 0.30723493
B10: 12.0x | C10: 0.11523255 | D10: 0.1549094 | E10: 0.18978164 | F10: 0.2209882 | G10: 0.24929642
A13: Table 2 — MOIC Sensitivity: Leverage (rows) vs. Exit Multiple (columns)
B14: Lev ↓ / Exit → | C14: 8.0x | D14: 9.0x | E14: 10.0x | F14: 11.0x | G14: 12.0x
B15: 4.0x | C15: 2.3919595 | D15: 2.7214664 | E15: 3.0509733 | F15: 3.3804802 | G15: 3.7099871
B16: 5.0x | C16: 2.6570905 | D16: 3.0704284 | E16: 3.4837663 | F16: 3.8971043 | G16: 4.3104422
B17: 6.0x | C17: 3.1981007 | D17: 3.7524803 | E17: 4.3068599 | F17: 4.8612395 | G17: 5.4156191
B18: 7.0x | C18: 4.4058887 | D18: 5.2474211 | E18: 6.0889535 | F18: 6.930486 | G18: 7.7720184
B19: 8.0x | C19: 8.3787734 | D19: 10.124588 | E19: 11.870403 | F19: 13.616217 | G19: 15.362032
A21: Note: Values computed from the model's operating projections and debt schedule across each assumption combination. "n/m" = not meaningful (debt would exceed purchase price, or negative equity).
A22: Base case returns: 39.3% IRR / 5.25x MOIC at 9.0x entry, 9.0x exit, 7.0x leverage.
