Workbook

Sheet Assumptions
A1: Reliance Industries Limited — Projection Assumptions
A2: Past Average derived from FY23-FY26 historicals; projection years reflect analyst-judgment trajectories.
A4: Assumption | B4: Past Average | C4: FY27E | D4: FY28E | E4: FY29E | F4: FY30E | G4: FY31E | H4: TERMINAL
A6: Revenue Growth % | B6: =AVERAGE('Profit & Loss'!C10/'Profit & Loss'!D10-1,'Profit & Loss'!D10/'Profit & Loss'!E10-1,'Profit & Loss'!E10/'Profit & Loss'!F10-1) -> 0.065088645 | C6: =B6 -> 0.065088645 | D6: =C6-0.5% -> 0.060088645 | E6: =D6-0.5% -> 0.055088645 | F6: =E6-0.5% -> 0.050088645 | G6: =F6-0.5% -> 0.045088645 | H6: 0.045
A7: COGS % Revenue | B7: =AVERAGE(SUM('Profit & Loss'!C15:C18)/'Profit & Loss'!C10,SUM('Profit & Loss'!D15:D18)/'Profit & Loss'!D10,SUM('Profit & Loss'!E15:E18)/'Profit & Loss'!E10,SUM('Profit & Loss'!F15:F18)/'Profit & Loss'!F10) -> 0.66142326 | C7: =B7-0.2% -> 0.65942326 | D7: =C7-0.2% -> 0.65742326 | E7: =D7-0.2% -> 0.65542326 | F7: =E7-0.2% -> 0.65342326 | G7: =F7-0.2% -> 0.65142326 | H7: =G7-0.2% -> 0.64942326
A8: SG&A % Revenue | B8: =AVERAGE(('Profit & Loss'!C19+'Profit & Loss'!C22)/'Profit & Loss'!C10,('Profit & Loss'!D19+'Profit & Loss'!D22)/'Profit & Loss'!D10,('Profit & Loss'!E19+'Profit & Loss'!E22)/'Profit & Loss'!E10,('Profit & Loss'!F19+'Profit & Loss'!F22)/'Profit & Loss'!F10) -> 0.1705616 | C8: =B8 -> 0.1705616 | D8: =C8 -> 0.1705616 | E8: =D8 -> 0.1705616 | F8: =E8 -> 0.1705616 | G8: =F8 -> 0.1705616 | H8: =G8 -> 0.1705616
A9: D&A % Revenue | B9: =AVERAGE('Profit & Loss'!C21/'Profit & Loss'!C10,'Profit & Loss'!D21/'Profit & Loss'!D10,'Profit & Loss'!E21/'Profit & Loss'!E10,'Profit & Loss'!F21/'Profit & Loss'!F10) -> 0.052161576 | C9: =B9+0.1% -> 0.053161576 | D9: =C9+0.1% -> 0.054161576 | E9: =D9+0.1% -> 0.055161576 | F9: =E9+0.1% -> 0.056161576 | G9: =F9+0.1% -> 0.057161576 | H9: =G9+0.1% -> 0.058161576
A10: Tax Rate | B10: =AVERAGE(('Profit & Loss'!C28+'Profit & Loss'!C29)/'Profit & Loss'!C25,('Profit & Loss'!D28+'Profit & Loss'!D29)/'Profit & Loss'!D25,('Profit & Loss'!E28+'Profit & Loss'!E29)/'Profit & Loss'!E25,('Profit & Loss'!F28+'Profit & Loss'!F29)/'Profit & Loss'!F25) -> 0.23119463 | C10: =B10 -> 0.23119463 | D10: =C10 -> 0.23119463 | E10: =D10 -> 0.23119463 | F10: =E10 -> 0.23119463 | G10: =F10 -> 0.23119463 | H10: =G10 -> 0.23119463
A11: DSO (Days Sales Outstanding) | B11: =AVERAGE('Balance Sheet'!C26/'Profit & Loss'!C10*365,'Balance Sheet'!D26/'Profit & Loss'!D10*365,'Balance Sheet'!E26/'Profit & Loss'!E10*365,'Balance Sheet'!F26/'Profit & Loss'!F10*365) -> 14.951663 | C11: 19.8 | D11: 17.4 | E11: =B11 -> 14.951663 | F11: =E11 -> 14.951663 | G11: =F11 -> 14.951663 | H11: =G11 -> 14.951663
A12: Inventory Days | B12: =AVERAGE('Balance Sheet'!C23/SUM('Profit & Loss'!C15:C18)*365,'Balance Sheet'!D23/SUM('Profit & Loss'!D15:D18)*365,'Balance Sheet'!E23/SUM('Profit & Loss'!E15:E18)*365,'Balance Sheet'!F23/SUM('Profit & Loss'!F15:F18)*365) -> 86.708268 | C12: =B12 -> 86.708268 | D12: =C12 -> 86.708268 | E12: =D12 -> 86.708268 | F12: =E12 -> 86.708268 | G12: =F12 -> 86.708268 | H12: =G12 -> 86.708268
A13: DPO (Days Payable Outstanding) | B13: =AVERAGE('Balance Sheet'!C57/SUM('Profit & Loss'!C15:C18)*365,'Balance Sheet'!D57/SUM('Profit & Loss'!D15:D18)*365,'Balance Sheet'!E57/SUM('Profit & Loss'!E15:E18)*365,'Balance Sheet'!F57/SUM('Profit & Loss'!F15:F18)*365) -> 96.412222 | C13: 82 | D13: 89.2 | E13: =B13 -> 96.412222 | F13: =E13 -> 96.412222 | G13: =F13 -> 96.412222 | H13: =G13 -> 96.412222
A14: Capex % Revenue | B14: =AVERAGE(-'Cash Flow Statement'!B27/'Profit & Loss'!C10,-'Cash Flow Statement'!C27/'Profit & Loss'!D10,-'Cash Flow Statement'!D27/'Profit & Loss'!E10,-'Cash Flow Statement'!E27/'Profit & Loss'!F10) -> 0.14560864 | C14: =B14-1% -> 0.13560864 | D14: =C14-1% -> 0.12560864 | E14: =D14-1% -> 0.11560864 | F14: =E14-1% -> 0.10560864 | G14: =F14-1% -> 0.095608641 | H14: =G14-1% -> 0.085608641
A15: Interest Rate on Debt | B15: =AVERAGE('Profit & Loss'!C20/(('Balance Sheet'!C44+'Balance Sheet'!C55+'Balance Sheet'!D44+'Balance Sheet'!D55)/2),'Profit & Loss'!D20/(('Balance Sheet'!D44+'Balance Sheet'!D55+'Balance Sheet'!E44+'Balance Sheet'!E55)/2),'Profit & Loss'!E20/(('Balance Sheet'!E44+'Balance Sheet'!E55+'Balance Sheet'!F44+'Balance Sheet'!F55)/2)) -> 0.07319421 | C15: =B15 -> 0.07319421 | D15: =C15 -> 0.07319421 | E15: =D15 -> 0.07319421 | F15: =E15 -> 0.07319421 | G15: =F15 -> 0.07319421 | H15: =G15 -> 0.07319421
A16: Dividend Payout % | B16: =AVERAGE(-'Cash Flow Statement'!B46/'Profit & Loss'!C43,-'Cash Flow Statement'!C46/'Profit & Loss'!D43,-'Cash Flow Statement'!D46/'Profit & Loss'!E43) -> 0.092249912 | C16: =10% -> 0.1 | D16: =C16+1% -> 0.11 | E16: =D16+1% -> 0.12 | F16: =E16+1% -> 0.13 | G16: =F16+1% -> 0.14 | H16: =G16+1% -> 0.15
A17: Other NCA | B17: =AVERAGE('Balance Sheet'!C21:E21) -> 0.1080288 | C17: =10% -> 0.1 | D17: =10% -> 0.1 | E17: =10% -> 0.1 | F17: =10% -> 0.1 | G17: =10% -> 0.1 | H17: =10% -> 0.1
A18: Loans%Revenue | B18: 0.004 | C18: 0.004 | D18: 0.004 | E18: 0.004 | F18: 0.004 | G18: 0.004 | H18: 0.004
A19: Investments%Revenue | B19: 0.1 | C19: 0.1 | D19: 0.1 | E19: 0.1 | F19: 0.1 | G19: 0.1 | H19: 0.1
A20: Other Fin Assets%Revenue | B20: 0.035 | C20: 0.035 | D20: 0.035 | E20: 0.035 | F20: 0.035 | G20: 0.035 | H20: 0.035
A21: Other Curr Assets%Revenue | B21: 0.05 | C21: 0.05 | D21: 0.05 | E21: 0.05 | F21: 0.05 | G21: 0.05 | H21: 0.05
A22: Non Controlling Interest | B22: ='Balance Sheet'!J39 -> 0.16904362 | C22: =B22 -> 0.16904362 | D22: =B22 -> 0.16904362 | E22: =B22 -> 0.16904362 | F22: =B22 -> 0.16904362 | G22: =B22 -> 0.16904362 | H22: =B22 -> 0.16904362
A23: Lease Liabilities%Revenue | B23: ='Balance Sheet'!J45 -> 0.015058452 | C23: =B23 -> 0.015058452 | D23: =C23 -> 0.015058452 | E23: =D23 -> 0.015058452 | F23: =E23 -> 0.015058452 | G23: =F23 -> 0.015058452 | H23: =G23 -> 0.015058452
A24: Deferred Payment Liabilities | B24: ='Balance Sheet'!J46 -> 0.0925484 | C24: =B24 -> 0.0925484 | D24: =C24 -> 0.0925484 | E24: =D24 -> 0.0925484 | F24: =E24 -> 0.0925484 | G24: =F24 -> 0.0925484 | H24: =G24 -> 0.0925484
A25: Other Financial Liabilities | B25: ='Balance Sheet'!J47 -> 0.035171404 | C25: =B25-0.2% -> 0.033171404 | D25: =C25-0.2% -> 0.031171404 | E25: =D25-0.2% -> 0.029171404 | F25: =E25-0.2% -> 0.027171404 | G25: =F25-0.2% -> 0.025171404 | H25: =G25-0.2% -> 0.023171404
A26: Non Current Provisions | B26: ='Balance Sheet'!J48 -> 0.020259837 | C26: =B26 -> 0.020259837 | D26: =C26 -> 0.020259837 | E26: =D26 -> 0.020259837 | F26: =E26 -> 0.020259837 | G26: =F26 -> 0.020259837 | H26: =G26 -> 0.020259837
A27: Current Provisions | B27: ='Balance Sheet'!J60 -> 0.0048323146 | C27: =B27 -> 0.0048323146 | D27: =C27 -> 0.0048323146 | E27: =D27 -> 0.0048323146 | F27: =E27 -> 0.0048323146 | G27: =F27 -> 0.0048323146 | H27: =G27 -> 0.0048323146
A28: Other Non-Current Liabilities | B28: ='Balance Sheet'!J50 -> 0.0064443257 | C28: =B28+0.05% -> 0.0069443257 | D28: =C28+0.05% -> 0.0074443257 | E28: =D28+0.05% -> 0.0079443257 | F28: =E28+0.05% -> 0.0084443257 | G28: =F28+0.05% -> 0.0089443257 | H28: =G28+0.05% -> 0.0094443257
A29: Lease Liabilities | B29: ='Balance Sheet'!J56 -> 0.006861738 | C29: =B29+0.05% -> 0.007361738 | D29: =C29+0.05% -> 0.007861738 | E29: =D29+0.05% -> 0.008361738 | F29: =E29+0.05% -> 0.008861738 | G29: =F29+0.05% -> 0.009361738 | H29: =G29+0.05% -> 0.009861738
A31: Other Financial Liabilities | B31: ='Balance Sheet'!J58 -> 0.060111093 | C31: =B31 -> 0.060111093 | D31: =C31 -> 0.060111093 | E31: =D31 -> 0.060111093 | F31: =E31 -> 0.060111093 | G31: =F31 -> 0.060111093 | H31: =G31 -> 0.060111093
A32: Other Current Liabilities | B32: ='Balance Sheet'!J59 -> 0.18732703 | C32: =B32 -> 0.18732703 | D32: =C32 -> 0.18732703 | E32: =D32 -> 0.18732703 | F32: =E32 -> 0.18732703 | G32: =F32 -> 0.18732703 | H32: =G32 -> 0.18732703
A33: Notes:
A34: • COGS = Cost of Materials Consumed + Purchase of Stock-in-Trade + Changes in Inventories + Excise Duty (rows 15-18 of P&L)
A35: • SG&A = Employee Benefits Expense + Other Expenses (rows 19, 22 of P&L) — Finance Costs and D&A excluded, modeled separately
A36: • Interest Rate on Debt uses average of opening + closing total borrowings (Non-Current + Current) per year; FY23 excluded (no FY22 balance available)
A37: • Dividend Payout % uses FY24-FY26 only (FY23 Cash Flow Statement has a known reconciliation gap — see Cash Flow Statement sheet note)
A38: • Projection columns (FY27E onward) taper toward long-run assumptions, anchored to historical averages.

Sheet Balance Sheet
A1: Reliance Industries Limited — Consolidated Balance Sheet
A2: As at 31st March, 2026 (₹ in crore)
A4: Particulars | B4: Note | C4: 31-Mar-2026 | D4: 31-Mar-2025 | E4: 31-Mar-2024 | F4: 31-Mar-2023 | G4: Growth Rates | J4: Percentage of Revenue
A5: ASSETS
A6: Non-Current Assets
A7: Property, Plant and Equipment | B7: 1 | C7: 751087 | D7: 683102 | E7: 606084 | F7: 570503
A8: Spectrum | B8: 1 | C8: 188120 | D8: 147122 | E8: 69852 | F8: 75351
A9: Other Intangible Assets | B9: 1 | C9: 157126 | D9: 144639 | E9: 89060 | F9: 63681
A10: Goodwill | B10: 1 | C10: 28462 | D10: 24530 | E10: 14989 | F10: 15270
A11: Capital Work-in-Progress | B11: 1 | C11: 192287 | D11: 169710 | E11: 152382 | F11: 117259
A12: Spectrum Under Development | B12: 1 | C12: 8611 | D12: 54176 | E12: 129602 | F12: 122357
A13: Other Intangible Assets Under Development | B13: 1 | C13: 36788 | D13: 38472 | E13: 56871 | F13: 54136
A14: Financial Assets
A15: Investments | B15: 2 | C15: 150901 | D15: 123672 | E15: 119502 | F15: 117087
A16: Loans | B16: 3 | C16: 826 | D16: 742 | E16: 899 | F16: 1525
A17: Other Financial Assets | B17: 4 | C17: 4899 | D17: 6088 | E17: 2622 | F17: 2523
A18: Deferred Tax Assets (Net) | B18: 5 | C18: 594 | D18: 408 | E18: 938 | F18: 1549
A19: Other Non-Current Assets | B19: 6 | C19: 64190 | D19: 58190 | E19: 43085 | F19: 40894
A20: Total Non-Current Assets | C20: =SUM(C7:C19) -> 1583891 | D20: =SUM(D7:D19) -> 1450851 | E20: =SUM(E7:E19) -> 1285886 | F20: =SUM(F7:F19) -> 1182135
C21: =(SUM(C15:C19)/SUM(D15:D19))-1 -> 0.17086198 | D21: =(SUM(D15:D19)/SUM(E15:E19))-1 -> 0.13202351 | E21: =(SUM(E15:E19)/SUM(F15:F19))-1 -> 0.021200895
A22: Current Assets
A23: Inventories | B23: 7 | C23: 166941 | D23: 146062 | E23: 152770 | F23: 140008
A24: Financial Assets
A25: Investments | B25: 8 | C25: 97431 | D25: 118709 | E25: 106170 | F25: 118473 | G25: =(C25/D25)-1 -> -0.17924504 | H25: =(D25/E25)-1 -> 0.11810304 | I25: =(E25/F25)-1 -> -0.10384645 | J25: =C25/'Profit & Loss'!C10 -> 0.090576615 | K25: =D25/'Profit & Loss'!D10 -> 0.12111482 | L25: =E25/'Profit & Loss'!E10 -> 0.11609978 | M25: =F25/'Profit & Loss'!F10 -> 0.13291993
A26: Trade Receivables | B26: 9 | C26: 58491 | D26: 42121 | E26: 31628 | F26: 28448
A27: Cash and Cash Equivalents | B27: 10 | C27: 145977 | D27: 106502 | E27: 97225 | F27: 68664
A28: Loans | C28: 4870 | D28: 5182 | E28: 2517 | F28: 176 | G28: =(C28/D28)-1 -> -0.060208414 | H28: =(D28/E28)-1 -> 1.0588002 | I28: =(E28/F28)-1 -> 13.301136 | J28: =C28/'Profit & Loss'!C$10 -> 0.0045273898 | K28: =D28/'Profit & Loss'!D$10 -> 0.0052870214 | L28: =E28/'Profit & Loss'!E$10 -> 0.0027524079 | M28: =F28/'Profit & Loss'!F$10 -> 0.00019746194
A29: Other Financial Assets | B29: 11 | C29: 57926 | D29: 23546 | E29: 23965 | F29: 19696 | G29: =(C29/D29)-1 -> 1.4601206 | H29: =(D29/E29)-1 -> -0.017483831 | I29: =(E29/F29)-1 -> 0.21674452 | J29: =C29/'Profit & Loss'!C$10 -> 0.053850838 | K29: =D29/'Profit & Loss'!D$10 -> 0.024023197 | L29: =E29/'Profit & Loss'!E$10 -> 0.026206379 | M29: =F29/'Profit & Loss'!F$10 -> 0.022097786
A30: Other Current Assets | B30: 12 | C30: 62613 | D30: 57148 | E30: 55825 | F30: 49831 | G30: =(C30/D30)-1 -> 0.095628893 | H30: =(D30/E30)-1 -> 0.02369906 | I30: =(E30/F30)-1 -> 0.12028657 | J30: =C30/'Profit & Loss'!C$10 -> 0.058208102 | K30: =D30/'Profit & Loss'!D$10 -> 0.058306194 | L30: =E30/'Profit & Loss'!E$10 -> 0.061046156 | M30: =F30/'Profit & Loss'!F$10 -> 0.055907534
A31: Total Current Assets | C31: =SUM(C23:C30) -> 594249 | D31: =SUM(D23:D30) -> 499270 | E31: =SUM(E23:E30) -> 470100 | F31: =SUM(F23:F30) -> 425296
A33: TOTAL ASSETS | C33: =SUM(C20,C31) -> 2178140 | D33: =SUM(D20,D31) -> 1950121 | E33: =SUM(E20,E31) -> 1755986 | F33: =F20+F31 -> 1607431
A35: EQUITY AND LIABILITIES
A36: Equity
A37: Equity Share Capital | B37: 14 | C37: 13532 | D37: 13532 | E37: 6766 | F37: 6766
A38: Other Equity | B38: 15 | C38: 890498 | D38: 829668 | E38: 786715 | F38: 709106 | G38: =(C38/D38)-1 -> 0.073318484 | H38: =(D38/E38)-1 -> 0.054597917 | I38: =(E38/F38)-1 -> 0.10944626
A39: Non-Controlling Interest | C39: 181836 | D39: 166426 | E39: 132307 | F39: 113009 | G39: =(C39/D39)-1 -> 0.092593705 | H39: =(D39/E39)-1 -> 0.25787751 | I39: =(E39/F39)-1 -> 0.17076516 | J39: =C39/'Profit & Loss'!C10 -> 0.16904362 | K39: =D39/'Profit & Loss'!D10 -> 0.16979889 | L39: =E39/'Profit & Loss'!E10 -> 0.1446813 | M39: =F39/'Profit & Loss'!F10 -> 0.12678964
A40: Total Equity | C40: =SUM(C37:C39) -> 1085866 | D40: =SUM(D37:D39) -> 1009626 | E40: =SUM(E37:E39) -> 925788 | F40: =SUM(F37:F39) -> 828881
A42: Non-Current Liabilities
A43: Financial Liabilities
A44: Borrowings | B44: 16 | C44: 270751 | D44: 236899 | E44: 222712 | F44: 183176
...

Sheet Profit & Loss
A1: Reliance Industries Limited — Consolidated Statement of Profit and Loss
A2: For the year ended 31st March, 2026 (₹ in crore)
A4: Particulars | B4: Note | C4: 2025-26 | D4: 2024-25 | E4: 2023-24 | F4: 2022-23
A5: Income
A6: Value of Sales | C6: 1043589 | D6: 960355 | E6: 883646 | F6: 856770
A7: Income from Services | C7: 132330 | D7: 110819 | E7: 116476 | F7: 118094
A8: Value of Sales & Services (Revenue) | C8: =C6+C7 -> 1175919 | D8: =D6+D7 -> 1071174 | E8: =E6+E7 -> 1000122 | F8: =F6+F7 -> 974864
A9: Less: GST Recovered | C9: 100244 | D9: 91038 | E9: 85650 | F9: 83553
A10: Revenue from Operations | B10: 25 | C10: =C8-C9 -> 1075675 | D10: =D8-D9 -> 980136 | E10: =E8-E9 -> 914472 | F10: =F8-F9 -> 891311
A11: Other Income | B11: 26 | C11: 28962 | D11: 17978 | E11: 16057 | F11: 11734
A12: Total Income | C12: =C10+C11 -> 1104637 | D12: =D10+D11 -> 998114 | E12: =E10+E11 -> 930529 | F12: =F10+F11 -> 903045
A14: Expenses
A15: Cost of Materials Consumed | C15: 443101 | D15: 422127 | E15: 400345 | F15: 450241
A16: Purchase of Stock-in-Trade | C16: 255829 | D16: 222686 | E16: 189881 | F16: 168505
A17: Changes in Inventories of Finished Goods, WIP and Stock-in-Trade | B17: 27 | C17: -10267 | D17: -15124 | E17: -4883 | F17: -30263
A18: Excise Duty | C18: 18456 | D18: 15443 | E18: 13408 | F18: 13476
A19: Employee Benefits Expense | B19: 28 | C19: 30318 | D19: 28559 | E19: 25679 | F19: 24872
A20: Finance Costs | B20: 29 | C20: 27061 | D20: 24269 | E20: 23118 | F20: 19571
A21: Depreciation / Amortisation and Depletion Expense | B21: 1 | C21: 57688 | D21: 53136 | E21: 50832 | F21: 40303
A22: Other Expenses | B22: 30 | C22: 159289 | D22: 141001 | E22: 127809 | F22: 122318
A23: Total Expenses | C23: =SUM(C15:C22) -> 981475 | D23: =SUM(D15:D22) -> 892097 | E23: =SUM(E15:E22) -> 826189 | F23: =SUM(F15:F22) -> 809023
A25: Profit Before Share of Profit/(Loss) of Associates/JVs and Tax | C25: =C12-C23 -> 123162 | D25: =D12-D23 -> 106017 | E25: =E12-E23 -> 104340 | F25: =F12-F23 -> 94022
A27: Tax Expenses
A28: Current Tax | B28: 13 | C28: 9736 | D28: 12758 | E28: 13590 | F28: 8398
A29: Deferred Tax | B29: 13 | C29: 17816 | D29: 12472 | E29: 12117 | F29: 11978
A30: Profit After Tax | C30: =C25-C28-C29 -> 95610 | D30: =D25-D28-D29 -> 80787 | E30: =E25-E28-E29 -> 78633 | F30: =F25-F28-F29 -> 73646
A31: Share of Profit/(Loss) of Associate and Joint Ventures | C31: 144 | D31: 522 | E31: 387 | F31: 24
A32: Profit for the year | C32: =C30+C31 -> 95754 | D32: =D30+D31 -> 81309 | E32: =E30+E31 -> 79020 | F32: =F30+F31 -> 73670
A34: Other Comprehensive Income
A35: Items that will not be reclassified to Profit or Loss | B35: 26.1 | C35: -337 | D35: -2904 | E35: 3852 | F35: -39
A36: Income Tax relating to items that will not be reclassified | B36: 26.1 | C36: 84 | D36: 438 | E36: -433 | F36: -13
A37: Items that will be reclassified to Profit or Loss | B37: 26.2 | C37: -14623 | D37: -214 | E37: 244 | F37: -9503
A38: Income Tax relating to items that will be reclassified | B38: 26.2 | C38: 3329 | D38: 244 | E38: 6 | F38: 1829
A39: Total Other Comprehensive Income/(Loss) for the Year (Net of Tax) | C39: =SUM(C35:C38) -> -11547 | D39: =SUM(D35:D38) -> -2436 | E39: =SUM(E35:E38) -> 3669 | F39: =SUM(F35:F38) -> -7726
A40: Total Comprehensive Income for the Year | C40: =C32+C39 -> 84207 | D40: =D32+D39 -> 78873 | E40: =E32+E39 -> 82689 | F40: =F32+F39 -> 65944
A42: Net Profit Attributable to:
A43: Owners of the Company | C43: 80775 | D43: 69648 | E43: 69621 | F43: 66702
A44: Non-Controlling Interest | C44: 14979 | D44: 11661 | E44: 9399 | F44: 7386
A46: Other Comprehensive Income Attributable to:
A47: Owners of the Company | C47: -11937 | D47: -2433 | E47: 3567 | F47: -18783
...

Sheet Changes in Equity
A1: Reliance Industries Limited — Consolidated Statement of Changes in Equity
A2: For the year ended 31st March, 2026 (₹ in crore)
A4: Particulars | B4: Balance as at 1-Apr-2025 | C4: Total Comprehensive Income | D4: Dividend | E4: Transfer (to)/ from Retained Earnings | F4: Transfer (to)/ from General Reserve | G4: On Rights Issue | H4: On Employee Stock Options | I4: Issue of Bonus Shares | J4: Others | K4: Balance as at 31-Mar-2026
A5: A. Equity Share Capital
A6: Equity Share Capital | B6: 13532 | C6: - | D6: - | E6: - | F6: - | G6: - | H6: - | I6: - | J6: - | K6: =SUM(B6:J6) -> 13532
A7: B. Other Equity — Reserves and Surplus
A8: Capital Reserve | B8: 280 | C8: - | D8: - | E8: - | F8: - | G8: - | H8: - | I8: - | J8: - | K8: =SUM(B8:J8) -> 280
A9: Capital Redemption Reserve | B9: 44 | C9: - | D9: - | E9: 1059 | F9: - | G9: - | H9: - | I9: - | J9: - | K9: =SUM(B9:J9) -> 1103
A10: Debenture Redemption Reserve | B10: 2069 | C10: - | D10: - | E10: 39 | F10: - | G10: - | H10: - | I10: - | J10: - | K10: =SUM(B10:J10) -> 2108
A11: Share Based Payments Reserve | B11: 790 | C11: - | D11: - | E11: - | F11: - | G11: - | H11: - | I11: -117 | J11: - | K11: =SUM(B11:J11) -> 673
A12: Statutory Reserve | B12: 603 | C12: - | D12: - | E12: 63 | F12: - | G12: - | H12: - | I12: - | J12: - | K12: =SUM(B12:J12) -> 666
A13: Securities Premium | B13: 93104 | C13: - | D13: - | E13: - | F13: - | G13: - | H13: - | I13: 14 | J13: - | K13: =SUM(B13:J13) -> 93118
A14: General Reserve | B14: 292704 | C14: - | D14: - | E14: - | F14: - | G14: - | H14: - | I14: - | J14: - | K14: =SUM(B14:J14) -> 292704
A15: Retained Earnings | B15: 391943 | C15: 80775 | D15: -7443 | E15: -1161 | F15: - | G15: - | H15: - | I15: - | J15: -470 | K15: =SUM(B15:J15) -> 463644
A16: Other Comprehensive Income
A17: Remeasurement of Defined Benefit Plan | B17: -333 | C17: -31 | D17: - | E17: - | F17: - | G17: - | H17: - | I17: - | J17: - | K17: =SUM(B17:J17) -> -364
A18: Equity Instruments through OCI | B18: 60897 | C18: -525 | D18: - | E18: - | F18: - | G18: - | H18: - | I18: - | J18: - | K18: =SUM(B18:J18) -> 60372
A19: Debt Instruments through OCI | B19: 2228 | C19: -195 | D19: - | E19: - | F19: - | G19: - | H19: - | I19: - | J19: - | K19: =SUM(B19:J19) -> 2033
A20: Cash Flow Hedge | B20: -14099 | C20: -12820 | D20: - | E20: - | F20: - | G20: - | H20: - | I20: - | J20: - | K20: =SUM(B20:J20) -> -26919
A21: Foreign Currency Translation Reserve | B21: -562 | C21: 1634 | D21: - | E21: - | F21: - | G21: - | H21: - | I21: - | J21: 8 | K21: =SUM(B21:J21) -> 1080
A22: Non-Controlling Interest | B22: 166426 | C22: 15369 | D22: -436 | E22: - | F22: - | G22: - | H22: - | I22: - | J22: 477 | K22: =SUM(B22:J22) -> 181836
A23: Total | B23: =SUM(B8:B15,B17:B22) -> 996094 | C23: =SUM(C8:C15,C17:C22) -> 84207 | D23: =SUM(D8:D15,D17:D22) -> -7879 | E23: =SUM(E8:E15,E17:E22) -> 0 | F23: =SUM(F8:F15,F17:F22) -> 0 | G23: =SUM(G8:G15,G17:G22) -> 0 | H23: =SUM(H8:H15,H17:H22) -> 0 | I23: =SUM(I8:I15,I17:I22) -> -103 | ... K23: =SUM(K8:K15,K17:K22) -> 1072334
A25: Note: Equity Share Capital — opening balance 1-Apr-2024 was ₹6,766 crore; rose to ₹13,532 crore by 31-Mar-2025 (bonus issue) and remained unchanged through 31-Mar-2026.
A26: Includes impact of change in non-controlling interest / acquisition, disposal & change in non-controlling interest where noted in source.
A27: Source: RIL Integrated Annual Report 2025-26, Consolidated Statement of Changes in Equity, pp.200-201
A29: FY 2024-25 Movement (For the year ended 31st March, 2025)
A31: Particulars | B31: Balance as at 1-Apr-2024 | C31: Total Comprehensive Income | D31: Dividend | E31: Transfer (to)/ from Retained Earnings | F31: Transfer (to)/ from General Reserve | G31: On Rights Issue | H31: On Employee Stock Options | I31: Issue of Bonus Shares | J31: Others | K31: Balance as at 31-Mar-2025
A32: A. Equity Share Capital
A33: Equity Share Capital | B33: 6766 | C33: - | D33: - | E33: - | F33: - | G33: - | H33: - | I33: - | J33: - | K33: 13532
A34: B. Other Equity — Reserves and Surplus
A35: Capital Reserve | B35: 280 | C35: - | D35: - | E35: - | F35: - | G35: - | H35: - | I35: - | J35: - | K35: 280
A36: Capital Redemption Reserve | B36: 44 | C36: - | D36: - | E36: - | F36: - | G36: - | H36: - | I36: - | J36: - | K36: 44
A37: Debenture Redemption Reserve | B37: 2314 | C37: - | D37: - | E37: -245 | F37: - | G37: - | H37: - | I37: - | J37: - | K37: 2069
A38: Share Based Payments Reserve | B38: 780 | C38: - | D38: - | E38: - | F38: - | G38: - | H38: 10 | I38: - | J38: - | K38: 790
A39: Statutory Reserve | B39: 445 | C39: - | D39: - | E39: 158 | F39: - | G39: - | H39: - | I39: - | J39: - | K39: 603
A40: Securities Premium | B40: 99802 | C40: - | D40: - | E40: - | F40: - | G40: 22 | H40: 46 | I40: -6766 | J40: - | K40: 93104
A41: General Reserve | B41: 292704 | C41: - | D41: - | E41: - | F41: - | G41: - | H41: - | I41: - | J41: - | K41: 292704
A42: Retained Earnings | B42: 339787 | C42: 69648 | D42: -6766 | E42: 87 | F42: - | G42: - | H42: - | I42: - | J42: -10813 | K42: 391943
A43: Other Comprehensive Income
A44: Remeasurement of Defined Benefit Plan | B44: -152 | C44: -181 | D44: - | E44: - | F44: - | G44: - | H44: - | I44: - | J44: - | K44: -333
...

Sheet Cash Flow Statement
A1: Reliance Industries Limited — Consolidated Statement of Cash Flows
A2: For the year ended 31st March, 2026 (₹ in crore)
A4: Particulars | B4: 2025-26 | C4: 2024-25 | D4: 2023-24 | E4: 2022-23
A5: A. Cash Flow from Operating Activities
A6: Net Profit Before Share of Profit/(Loss) of Associates/JVs and Tax | B6: 123162 | C6: 106017 | D6: 104340 | E6: 94022
A7: Adjusted for:
A8: Loss on Sale/Discard of PP&E and Other Intangible Assets (Net) | B8: 143 | C8: 135 | D8: 178 | E8: -60
A9: Depreciation / Amortisation and Depletion Expense | B9: 57688 | C9: 53136 | D9: 50832 | E9: 40303
A10: Effect of Exchange Rate Change | B10: 6518 | C10: -2182 | D10: -1330 | E10: -3680
A11: Net Gain on Financial Assets | B11: -2946 | C11: -1557 | D11: -1921 | E11: 1214
A12: Dividend Income | B12: -9100 | C12: -504 | D12: -89 | E12: -38
A13: Interest Income | B13: -13302 | C13: -12410 | D13: -10745 | E13: -11240
A14: Finance Costs | B14: 27061 | C14: 24269 | D14: 23118 | E14: 19571
A15: Sub-Total | B15: =SUM(B8:B14) -> 66062 | C15: =SUM(C8:C14) -> 60887 | D15: =SUM(D8:D14) -> 60043 | E15: =SUM(E8:E14) -> 46070
A16: Operating Profit before Working Capital Changes | B16: =B6+B15 -> 189224 | C16: =C6+C15 -> 166904 | D16: =D6+D15 -> 164383 | E16: =E6+E15 -> 140092
A17: Adjusted for:
A18: Trade and Other Receivables | B18: -53322 | C18: -17837 | D18: -15674 | E18: 13194
A19: Inventories | B19: -20790 | C19: 3134 | D19: -12756 | E19: -32228
A20: Trade and Other Payables | B20: 86609 | C20: 38427 | D20: 34796 | E20: -600
A21: Sub-Total | B21: =SUM(B18:B20) -> 12497 | C21: =SUM(C18:C20) -> 23724 | D21: =SUM(D18:D20) -> 6366 | E21: =SUM(E18:E20) -> -19634
A22: Cash Generated from Operations | B22: =B16+B21 -> 201721 | C22: =C16+C21 -> 190628 | D22: =D16+D21 -> 170749 | E22: =E16+E21 -> 120458
A23: Taxes Paid (Net) | B23: -9608 | C23: -11925 | D23: -11961 | E23: -6297
A24: Net Cash Flow from Operating Activities * | B24: =B22+B23 -> 192113 | C24: =C22+C23 -> 178703 | D24: =D22+D23 -> 158788 | E24: =E22+E23 -> 114161
A26: B. Cash Flow from Investing Activities
A27: Expenditure for PP&E, Spectrum and Other Intangible Assets | B27: -122916 | C27: -139967 | D27: -152883 | E27: -140988
A28: Proceeds from disposal of PP&E and Other Intangible Assets | B28: 826 | C28: 2343 | D28: 15307 | E28: 9186
A29: Purchase of Investments | B29: -988777 | C29: -684340 | D29: -513660 | E29: -471822
A30: Proceeds from Sale of Financial Assets | B30: 991876 | C30: 672558 | D30: 531355 | E30: 501266
A31: Payment of Deferred Payment Liabilities | B31: -4736 | C31: -4574 | D31: -4423 | E31: 0
A32: Interest Income | B32: 13538 | C32: 15833 | D32: 10648 | E32: 11103
A33: Dividend Income from Associates | B33: 49 | C33: 49 | D33: 59 | E33: 17
A34: Dividend Income from Others | B34: 9051 | C34: 563 | D34: 16 | E34: 3
A35: Net Cash Used in Investing Activities | B35: =SUM(B27:B34) -> -101089 | C35: =SUM(C27:C34) -> -137535 | D35: =SUM(D27:D34) -> -113581 | E35: =SUM(E27:E34) -> -91235
A37: C. Cash Flow from Financing Activities
A38: Proceeds from Issue of Share Capital to Non-Controlling Interest (Net of Dividend Paid) | B38: - | C38: - | D38: 20915 | E38: 479
A39: Proceeds from Issue of Equity Share Capital @ | B39: - | C39: - | D39: - | E39: 0
A40: Net Proceeds from Rights Issue | B40: - | C40: 22 | D40: 7 | E40: 40
A41: Payments to Non-Controlling Interest Shareholders towards Capital Reduction | B41: - | C41: - | D41: -1085 | E41: 0
A42: Payment of Lease Liabilities | B42: -6508 | C42: -2956 | D42: -2483 | E42: -1406
A43: Proceeds from Borrowings - Non-current (incl. Current Maturities) | B43: 38871 | C43: 26378 | D43: 69610 | E43: 35936
...

Sheet Projected Cash Flow
A1: Reliance Industries Limited — Projected Cash Flow Statement
B3: Particulars | C3: FY26A | D3: FY27E | E3: FY28E | F3: FY29E | G3: FY30E | H3: FY31E
A5: A. Cash Flow from Operating Activities
A6: Net Profit | C6: ='Projected Profit and Loss'!C16 -> 95610 | D6: ='Projected Profit and Loss'!D16 -> 103947.96 | E6: ='Projected Profit and Loss'!E16 -> 111338.5 | F6: ='Projected Profit and Loss'!F16 -> 119536.39 | G6: ='Projected Profit and Loss'!G16 -> 127744.71 | H6: ='Projected Profit and Loss'!H16 -> 135883.83
A7: Add: Depreciation/Amortisation | C7: ='Projected Profit and Loss'!C10*-1 -> 57688 | D7: =-'Projected Profit and Loss'!D10 -> 60906.645 | E7: =-'Projected Profit and Loss'!E10 -> 65780.975 | F7: =-'Projected Profit and Loss'!F10 -> 70686.198 | G7: =-'Projected Profit and Loss'!G10 -> 75572.399 | H7: =-'Projected Profit and Loss'!H10 -> 80386.153
A8: Add: Interest Expense (added back, shown in Financing) | C8: ='Projected Profit and Loss'!C12*-1 -> 27061 | D8: =-'Projected Profit and Loss'!D12 -> 27632.741 | E8: =-'Projected Profit and Loss'!E12 -> 27278.794 | F8: =-'Projected Profit and Loss'!F12 -> 25782.31 | G8: =-'Projected Profit and Loss'!G12 -> 24079.892 | H8: =-'Projected Profit and Loss'!H12 -> 22171.274
A9: Less: Increase in Trade Receivables | C9: =-('Projected Balance Sheet'!C13-'Balance Sheet'!D26) -> -16370 | D9: =-('Projected Balance Sheet'!D13-'Projected Balance Sheet'!C13) -> -3658.7171 | E9: =-('Projected Balance Sheet'!E13-'Projected Balance Sheet'!D13) -> 4251.4725 | F9: =-('Projected Balance Sheet'!F13-'Projected Balance Sheet'!E13) -> 5406.0645 | G9: =-('Projected Balance Sheet'!G13-'Projected Balance Sheet'!F13) -> -2629.2622 | H9: =-('Projected Balance Sheet'!H13-'Projected Balance Sheet'!G13) -> -2485.3512
A10: Add: Increase in Trade Payables | C10: ='Projected Balance Sheet'!C45-'Balance Sheet'!D57 -> -27947 | D10: ='Projected Balance Sheet'!D45-'Projected Balance Sheet'!C45 -> 10885.449 | E10: ='Projected Balance Sheet'!E45-'Projected Balance Sheet'!D45 -> 25403.462 | F10: ='Projected Balance Sheet'!F45-'Projected Balance Sheet'!E45 -> 26718.89 | G10: ='Projected Balance Sheet'!G45-'Projected Balance Sheet'!F45 -> 10401.281 | H10: ='Projected Balance Sheet'!H45-'Projected Balance Sheet'!G45 -> 9728.9594
A11: Less: Increase in Inventories | C11: =-('Projected Balance Sheet'!C10-'Balance Sheet'!D23) -> -20879 | D11: =-('Projected Balance Sheet'!D10-'Projected Balance Sheet'!C10) -> -12531.843 | E11: =-('Projected Balance Sheet'!E10-'Projected Balance Sheet'!D10) -> -10207.239 | F11: =-('Projected Balance Sheet'!F10-'Projected Balance Sheet'!E10) -> -9840.3894 | G11: =-('Projected Balance Sheet'!G10-'Projected Balance Sheet'!F10) -> -9354.3853 | H11: =-('Projected Balance Sheet'!H10-'Projected Balance Sheet'!G10) -> -8749.7332
A12: Net Cash from Operating Activities | C12: =SUM(C6:C11) -> 115163 | D12: =SUM(D6:D11) -> 187182.24 | E12: =SUM(E6:E11) -> 223845.97 | F12: =SUM(F6:F11) -> 238289.46 | G12: =SUM(G6:G11) -> 225814.63 | H12: =SUM(H6:H11) -> 236935.14
A14: B. Cash Flow from Investing Activities
A15: Less: Capex | C15: ='Projected Profit and Loss'!C19*-1 -> -122916 | D15: =-'Projected Profit and Loss'!D19 -> -155365.36 | E15: =-'Projected Profit and Loss'!E19 -> -152555.73 | F15: =-'Projected Profit and Loss'!F19 -> -148145.43 | G15: =-'Projected Profit and Loss'!G19 -> -142109.59 | H15: =-'Projected Profit and Loss'!H19 -> -134454.15
A16: Net Cash used in Investing Activities | C16: =C15 -> -122916 | D16: =D15 -> -155365.36 | E16: =E15 -> -152555.73 | F16: =F15 -> -148145.43 | G16: =G15 -> -142109.59 | H16: =H15 -> -134454.15
A18: C. Cash Flow from Financing Activities
A19: Less: Interest Paid | C19: =C8*-1 -> -27061 | D19: =-'Debt Schedule'!D18 -> -27632.741 | E19: =-'Debt Schedule'!E18 -> -27278.794 | F19: =-'Debt Schedule'!F18 -> -25782.31 | G19: =-'Debt Schedule'!G18 -> -24079.892 | H19: =-'Debt Schedule'!H18 -> -22171.274
A20: Less: Dividends Paid | C20: =-('Projected Profit and Loss'!C16*Assumptions!B16) -> -8820.0141 | D20: =-'Projected Profit and Loss'!D16*Assumptions!C16 -> -10394.796 | E20: =-'Projected Profit and Loss'!E16*Assumptions!D16 -> -12247.235 | F20: =-'Projected Profit and Loss'!F16*Assumptions!E16 -> -14344.366 | G20: =-'Projected Profit and Loss'!G16*Assumptions!F16 -> -16606.812 | H20: =-'Projected Profit and Loss'!H16*Assumptions!G16 -> -19023.737
A21: Net Borrowing/(Repayment) | C21: ='Balance Sheet'!C44+'Balance Sheet'!C55-('Balance Sheet'!D44+'Balance Sheet'!D55) -> 26891 | D21: ='Debt Schedule'!D9 -> 6210.6584 | E21: ='Debt Schedule'!E9 -> -15882.103 | F21: ='Debt Schedule'!F9 -> -25008.677 | G21: ='Debt Schedule'!G9 -> -21509.171 | H21: ='Debt Schedule'!H9 -> -30642.99
A22: Net Cash from Financing Activities | C22: =SUM(C19:C21) -> -8990.0141 | D22: =SUM(D19:D21) -> -31816.879 | E22: =SUM(E19:E21) -> -55408.133 | F22: =SUM(F19:F21) -> -65135.353 | G22: =SUM(G19:G21) -> -62195.875 | H22: =SUM(H19:H21) -> -71838
A24: Net Change in Cash | C24: =C12+C16+C22 -> -16743.014 | D24: =D12+D16+D22 -> 0 | E24: =E12+E16+E22 -> 15882.103 | F24: =F12+F16+F22 -> 25008.677 | G24: =G12+G16+G22 -> 21509.171 | H24: =H12+H16+H22 -> 30642.99
A25: Opening Cash Balance | C25: ='Balance Sheet'!D27 -> 106502 | D25: ='Balance Sheet'!C27 -> 145977 | E25: =D26 -> 145977 | F25: =E26 -> 161859.1 | G25: =F26 -> 186867.78 | H25: =G26 -> 208376.95
A26: Closing Cash Balance | C26: =C24+C25 -> 89758.986 | D26: =D24+D25 -> 145977 | E26: =E24+E25 -> 161859.1 | F26: =F24+F25 -> 186867.78 | G26: =G24+G25 -> 208376.95 | H26: =H24+H25 -> 239019.94
A28: Note: This is a simplified CFS (Net Profit, D&A, Interest, Working Capital, Capex, Dividends, Net Borrowing only). It will NOT tie exactly to the actual reported FY26 cash flow, which includes Other Income components, Investment purchases/sales, and other items not modeled here. This is standard for a projection-driven 3-statement model.

Sheet Projected Balance Sheet
C3: FY26A | D3: FY27E | E3: FY28E | F3: FY29E | G3: FY30E | H3: FY31E
B4: NON CURRENT ASSETS
B5: PP&E, and Other Capex Items | C5: =SUM('Balance Sheet'!C7:C13) -> 1362481 | D5: =C5+'Projected Profit and Loss'!D19+'Projected Profit and Loss'!D10 -> 1456939.7 | E5: =D5+'Projected Profit and Loss'!E19+'Projected Profit and Loss'!E10 -> 1543714.5 | F5: =E5+'Projected Profit and Loss'!F19+'Projected Profit and Loss'!F10 -> 1621173.7 | G5: =F5+'Projected Profit and Loss'!G19+'Projected Profit and Loss'!G10 -> 1687710.9 | H5: =G5+'Projected Profit and Loss'!H19+'Projected Profit and Loss'!H10 -> 1741778.9
B6: Other Non Current Assets | C6: =SUM('Balance Sheet'!C15:C19) -> 221410 | D6: =C6 -> 221410 | E6: =D6 -> 221410 | F6: =E6 -> 221410 | G6: =F6 -> 221410 | H6: =G6 -> 221410
B7: Total Non Current Assets | C7: =SUM(C5:C6) -> 1583891 | D7: =SUM(D5:D6) -> 1678349.7 | E7: =SUM(E5:E6) -> 1765124.5 | F7: =SUM(F5:F6) -> 1842583.7 | G7: =SUM(G5:G6) -> 1909120.9 | H7: =SUM(H5:H6) -> 1963188.9
B9: CURRENT ASSETS
B10: Inventories | C10: ='Balance Sheet'!C23 -> 166941 | D10: =(-'Projected Profit and Loss'!D7*Assumptions!C12)/365 -> 179472.84 | E10: =(-'Projected Profit and Loss'!E7*Assumptions!D12)/365 -> 189680.08 | F10: =(-'Projected Profit and Loss'!F7*Assumptions!E12)/365 -> 199520.47 | G10: =(-'Projected Profit and Loss'!G7*Assumptions!F12)/365 -> 208874.86 | H10: =(-'Projected Profit and Loss'!H7*Assumptions!G12)/365 -> 217624.59
B11: Financial Assets
B12: Investments | C12: ='Balance Sheet'!C25 -> 97431 | D12: =C12 -> 97431 | E12: =D12 -> 97431 | F12: =E12 -> 97431 | G12: =F12 -> 97431 | H12: =G12 -> 97431
B13: Trade Receivables | C13: ='Balance Sheet'!C26 -> 58491 | D13: =('Projected Profit and Loss'!D6*Assumptions!C11)/365 -> 62149.717 | E13: =('Projected Profit and Loss'!E6*Assumptions!D11)/365 -> 57898.245 | F13: =('Projected Profit and Loss'!F6*Assumptions!E11)/365 -> 52492.18 | G13: =('Projected Profit and Loss'!G6*Assumptions!F11)/365 -> 55121.442 | H13: =('Projected Profit and Loss'!H6*Assumptions!G11)/365 -> 57606.794
B14: Cash and Cash Equivalents | C14: ='Balance Sheet'!C27 -> 145977 | D14: ='Projected Cash Flow'!D26 -> 145977 | E14: ='Projected Cash Flow'!E26 -> 161859.1 | F14: ='Projected Cash Flow'!F26 -> 186867.78 | G14: ='Projected Cash Flow'!G26 -> 208376.95 | H14: ='Projected Cash Flow'!H26 -> 239019.94
B15: Loans | C15: ='Balance Sheet'!C28 -> 4870 | D15: =C15 -> 4870 | E15: =D15 -> 4870 | F15: =E15 -> 4870 | G15: =F15 -> 4870 | H15: =G15 -> 4870
B16: Other Financial Assets | C16: ='Balance Sheet'!C29 -> 57926 | D16: =C16 -> 57926 | E16: =D16 -> 57926 | F16: =E16 -> 57926 | G16: =F16 -> 57926 | H16: =G16 -> 57926
B17: Other Current Assets | C17: ='Balance Sheet'!C30 -> 62613 | D17: =C17 -> 62613 | E17: =D17 -> 62613 | F17: =E17 -> 62613 | G17: =F17 -> 62613 | H17: =G17 -> 62613
B18: Total Current Assets | C18: =SUM(C10:C17) -> 594249 | D18: =SUM(D10:D17) -> 610439.56 | E18: =SUM(E10:E17) -> 632277.43 | F18: =SUM(F10:F17) -> 661720.43 | G18: =SUM(G10:G17) -> 695213.25 | H18: =SUM(H10:H17) -> 737091.32
B20: TOTAL ASSETS | C20: =C7+C18 -> 2178140 | D20: =D7+D18 -> 2288789.3 | E20: =E7+E18 -> 2397401.9 | F20: =F7+F18 -> 2504304.1 | G20: =G7+G18 -> 2604334.1 | H20: =H7+H18 -> 2700280.2
B22: EQUITY AND LIABILITIES
B23: Equity
B24: Equity Share Capital | C24: ='Balance Sheet'!C37 -> 13532 | D24: =C24 -> 13532 | E24: =D24 -> 13532 | F24: =E24 -> 13532 | G24: =F24 -> 13532 | H24: =G24 -> 13532
B25: Other Equity | C25: ='Balance Sheet'!C38 -> 890498 | D25: =C25+'Projected Profit and Loss'!D16-('Projected Profit and Loss'!D16*Assumptions!C16) -> 984051.17 | E25: =D25+'Projected Profit and Loss'!E16-('Projected Profit and Loss'!E16*Assumptions!D16) -> 1083142.4 | F25: =E25+'Projected Profit and Loss'!F16-('Projected Profit and Loss'!F16*Assumptions!E16) -> 1188334.5 | G25: =F25+'Projected Profit and Loss'!G16-('Projected Profit and Loss'!G16*Assumptions!F16) -> 1299472.4 | H25: =G25+'Projected Profit and Loss'!H16-('Projected Profit and Loss'!H16*Assumptions!G16) -> 1416332.4
B26: Non-Controlling Interest | C26: ='Balance Sheet'!C39 -> 181836 | D26: =C26 -> 181836 | E26: =C26 -> 181836 | F26: =C26 -> 181836 | G26: =C26 -> 181836 | H26: =C26 -> 181836
B27: Total Equity | C27: =SUM(C24:C26) -> 1085866 | D27: =SUM(D24:D26) -> 1179419.2 | E27: =SUM(E24:E26) -> 1278510.4 | F27: =SUM(F24:F26) -> 1383702.5 | G27: =SUM(G24:G26) -> 1494840.4 | H27: =SUM(H24:H26) -> 1611700.4
B29: Non-Current Liabilities
B30: Financial Liabilities
B31: Borrowings | C31: ='Debt Schedule'!C15 -> 270751 | D31: ='Debt Schedule'!D15 -> 275242.05 | E31: ='Debt Schedule'!E15 -> 263757.39 | F31: ='Debt Schedule'!F15 -> 245673.14 | G31: ='Debt Schedule'!G15 -> 230119.45 | H31: ='Debt Schedule'!H15 -> 207960.91
B32: Lease Liabilities | C32: ='Balance Sheet'!C56 -> 7381 | D32: =C32 -> 7381 | E32: =D32 -> 7381 | F32: =E32 -> 7381 | G32: =F32 -> 7381 | H32: =G32 -> 7381
B33: Deferred Payment Liabilities | C33: ='Balance Sheet'!C46 -> 99552 | D33: =C33 -> 99552 | E33: =D33 -> 99552 | F33: =E33 -> 99552 | G33: =F33 -> 99552 | H33: =G33 -> 99552
B34: Other Financial Liabilities | C34: ='Balance Sheet'!C47 -> 37833 | D34: =C34 -> 37833 | E34: =D34 -> 37833 | F34: =E34 -> 37833 | G34: =F34 -> 37833 | H34: =G34 -> 37833
B35: Provisions | C35: ='Balance Sheet'!C48 -> 21793 | D35: =C35 -> 21793 | E35: =D35 -> 21793 | F35: =E35 -> 21793 | G35: =F35 -> 21793 | H35: =G35 -> 21793
B36: Deferred Tax Liabilities (Net) | C36: ='Balance Sheet'!C49 -> 97961 | D36: =C36 -> 97961 | E36: =D36 -> 97961 | F36: =E36 -> 97961 | G36: =F36 -> 97961 | H36: =G36 -> 97961
B37: Other Non-Current Liabilities | C37: ='Balance Sheet'!C50 -> 6932 | D37: =C37 -> 6932 | E37: =D37 -> 6932 | F37: =E37 -> 6932 | G37: =F37 -> 6932 | H37: =G37 -> 6932
B38: Total Non-Current Liabilities | C38: =SUM(C31:C37) -> 542203 | D38: =SUM(D31:D37) -> 546694.05 | E38: =SUM(E31:E37) -> 535209.39 | F38: =SUM(F31:F37) -> 517125.14 | G38: =SUM(G31:G37) -> 501571.45 | H38: =SUM(H31:H37) -> 479412.91
A40: Current Liabilities
A41: Financial Liabilities
A42: Borrowings | C42: ='Debt Schedule'!C16 -> 103670 | D42: ='Debt Schedule'!D16 -> 105389.61 | E42: ='Debt Schedule'!E16 -> 100992.16 | F42: ='Debt Schedule'!F16 -> 94067.739 | G42: ='Debt Schedule'!G16 -> 88112.262 | H42: ='Debt Schedule'!H16 -> 79627.805
A44: Lease Liabilities | C44: ='Balance Sheet'!C45 -> 16198 | D44: =C44 -> 16198 | E44: =D44 -> 16198 | F44: =E44 -> 16198 | G44: =F44 -> 16198 | H44: =G44 -> 16198
A45: Trade Payables | C45: ='Balance Sheet'!C57 -> 158842 | D45: =(-'Projected Profit and Loss'!D7*Assumptions!C13)/365 -> 169727.45 | E45: =(-'Projected Profit and Loss'!E7*Assumptions!D13)/365 -> 195130.91 | F45: =(-'Projected Profit and Loss'!F7*Assumptions!E13)/365 -> 221849.8 | G45: =(-'Projected Profit and Loss'!G7*Assumptions!F13)/365 -> 232251.08 | H45: =(-'Projected Profit and Loss'!H7*Assumptions!G13)/365 -> 241980.04
A46: Other Financial Liabilities | C46: ='Balance Sheet'!C58 -> 64660 | D46: =C46 -> 64660 | E46: =D46 -> 64660 | F46: =E46 -> 64660 | G46: =F46 -> 64660 | H46: =G46 -> 64660
A47: Other Current Liabilities | C47: ='Balance Sheet'!C59 -> 201503 | D47: =C47 -> 201503 | E47: =D47 -> 201503 | F47: =E47 -> 201503 | G47: =F47 -> 201503 | H47: =G47 -> 201503
A48: Provisions | C48: ='Balance Sheet'!C60 -> 5198 | D48: =C48 -> 5198 | E48: =D48 -> 5198 | F48: =E48 -> 5198 | G48: =F48 -> 5198 | H48: =G48 -> 5198
...

Sheet Debt Schedule
A1: Reliance Industries Limited — Debt Schedule
B3: Particulars | C3: FY26A | D3: FY27E | E3: FY28E | F3: FY29E | G3: FY30E | H3: FY31E
A5: Opening Total Debt (Non-Current + Current Borrowings) | C5: ='Balance Sheet'!D44+'Balance Sheet'!D55 -> 347530 | D5: =C12 -> 374421 | E5: =D12 -> 380631.66 | F5: =E12 -> 364749.55 | G5: =F12 -> 339740.88 | H5: =G12 -> 318231.71
A6: Add: Cash Flow Surplus/(Deficit) Before Financing | C6: ='Projected Cash Flow'!C12+'Projected Cash Flow'!C16+'Projected Cash Flow'!C19+'Projected Cash Flow'!C20 -> -43634.014 | D6: ='Projected Cash Flow'!D12+'Projected Cash Flow'!D16+'Projected Cash Flow'!D19+'Projected Cash Flow'!D20 -> -6210.6584 | E6: ='Projected Cash Flow'!E12+'Projected Cash Flow'!E16+'Projected Cash Flow'!E19+'Projected Cash Flow'!E20 -> 31764.207 | F6: ='Projected Cash Flow'!F12+'Projected Cash Flow'!F16+'Projected Cash Flow'!F19+'Projected Cash Flow'!F20 -> 50017.353 | G6: ='Projected Cash Flow'!G12+'Projected Cash Flow'!G16+'Projected Cash Flow'!G19+'Projected Cash Flow'!G20 -> 43018.342 | H6: ='Projected Cash Flow'!H12+'Projected Cash Flow'!H16+'Projected Cash Flow'!H19+'Projected Cash Flow'!H20 -> 61285.979
A7: Note: Cash available before financing = Operating CF + Investing CF + interest and dividends paid.
A9: Net Borrowing / (Repayment) for the year | C9: =IF(C6>0,-MIN(C6*0.5,C5),-C6) -> 43634.014 | D9: =IF(D6>0,-MIN(D6*0.5,D5),-D6) -> 6210.6584 | E9: =IF(E6>0,-MIN(E6*0.5,E5),-E6) -> -15882.103 | F9: =IF(F6>0,-MIN(F6*0.5,F5),-F6) -> -25008.677 | G9: =IF(G6>0,-MIN(G6*0.5,G5),-G6) -> -21509.171 | H9: =IF(H6>0,-MIN(H6*0.5,H5),-H6) -> -30642.99
A10: Note: Net borrowing follows a 50% cash sweep — half of any surplus repays debt, with debt floored at zero.
A12: Closing Total Debt | C12: =C15+C16 -> 374421 | D12: =MAX(0,D5+D9) -> 380631.66 | E12: =MAX(0,E5+E9) -> 364749.55 | F12: =MAX(0,F5+F9) -> 339740.88 | G12: =MAX(0,G5+G9) -> 318231.71 | H12: =MAX(0,H5+H9) -> 287588.72
A14: Memo: Closing Debt Split
A15: Non-Current Borrowings (held at FY26A mix %) | C15: ='Balance Sheet'!C44 -> 270751 | D15: =(C15/(C15+C16))*D12 -> 275242.05 | E15: =(D15/(D15+D16))*E12 -> 263757.39 | F15: =(E15/(E15+E16))*F12 -> 245673.14 | G15: =(F15/(F15+F16))*G12 -> 230119.45 | H15: =(G15/(G15+G16))*H12 -> 207960.91
A16: Current Borrowings (held at FY26A mix %) | C16: ='Balance Sheet'!C55 -> 103670 | D16: =D12-D15 -> 105389.61 | E16: =E12-E15 -> 100992.16 | F16: =F12-F15 -> 94067.739 | G16: =G12-G15 -> 88112.262 | H16: =H12-H15 -> 79627.805
A18: Interest Expense Check (Closing Debt × Interest Rate) | C18: =((C5+C12)/2)*Assumptions!B15 -> 26421.317 | D18: =((D5+D12)/2)*Assumptions!C15 -> 27632.741 | E18: =((E5+E12)/2)*Assumptions!D15 -> 27278.794 | F18: =((F5+F12)/2)*Assumptions!E15 -> 25782.31 | G18: =((G5+G12)/2)*Assumptions!F15 -> 24079.892 | H18: =((H5+H12)/2)*Assumptions!G15 -> 22171.274

Sheet Projected Profit and Loss
C4: FY26A | D4: FY27E | E4: FY28E | F4: FY29E | G4: FY30E | H4: FY31E
B6: Revenue from Operations | C6: ='Profit & Loss'!C10 -> 1075675 | D6: =C6*(1+Assumptions!C6) -> 1145689.2 | E6: =D6*(1+Assumptions!D6) -> 1214532.1 | F6: =E6*(1+Assumptions!E6) -> 1281439.1 | G6: =F6*(1+Assumptions!F6) -> 1345624.6 | H6: =G6*(1+Assumptions!G6) -> 1406297
B7: Less: COGS | C7: =-SUM('Profit & Loss'!C15:C18) -> -707119 | D7: =-Assumptions!C7*'Projected Profit and Loss'!D6 -> -755494.13 | E7: =-Assumptions!D7*'Projected Profit and Loss'!E6 -> -798461.69 | F7: =-Assumptions!E7*'Projected Profit and Loss'!F6 -> -839884.98 | G7: =-Assumptions!F7*'Projected Profit and Loss'!G6 -> -879262.43 | H7: =-Assumptions!G7*'Projected Profit and Loss'!H6 -> -916094.59
B8: Gross Profit | C8: =SUM(C6:C7) -> 368556 | D8: =SUM(D6:D7) -> 390195.1 | E8: =SUM(E6:E7) -> 416070.46 | F8: =SUM(F6:F7) -> 441554.09 | G8: =SUM(G6:G7) -> 466362.19 | H8: =SUM(H6:H7) -> 490202.42
B9: Less: SG&A | C9: =-SUM('Profit & Loss'!C19,'Profit & Loss'!C22) -> -189607 | D9: =-Assumptions!C8*'Projected Profit and Loss'!D6 -> -195410.59 | E9: =-Assumptions!D8*'Projected Profit and Loss'!E6 -> -207152.54 | F9: =-Assumptions!E8*'Projected Profit and Loss'!F6 -> -218564.3 | G9: =-Assumptions!F8*'Projected Profit and Loss'!G6 -> -229511.89 | H9: =-Assumptions!G8*'Projected Profit and Loss'!H6 -> -239860.27
B10: Less:D&A | C10: =-SUM('Profit & Loss'!C21) -> -57688 | D10: =-Assumptions!C9*'Projected Profit and Loss'!D6 -> -60906.645 | E10: =-Assumptions!D9*'Projected Profit and Loss'!E6 -> -65780.975 | F10: =-Assumptions!E9*'Projected Profit and Loss'!F6 -> -70686.198 | G10: =-Assumptions!F9*'Projected Profit and Loss'!G6 -> -75572.399 | H10: =-Assumptions!G9*'Projected Profit and Loss'!H6 -> -80386.153
B11: EBIT | C11: =SUM(C8:C10) -> 121261 | D11: =SUM(D8:D10) -> 133877.87 | E11: =SUM(E8:E10) -> 143136.94 | F11: =SUM(F8:F10) -> 152303.6 | G11: =SUM(G8:G10) -> 161277.9 | H11: =SUM(H8:H10) -> 169956
B12: Less: Finance Costs | C12: =-'Profit & Loss'!C20 -> -27061 | D12: =-'Debt Schedule'!D18 -> -27632.741 | E12: =-'Debt Schedule'!E18 -> -27278.794 | F12: =-'Debt Schedule'!F18 -> -25782.31 | G12: =-'Debt Schedule'!G18 -> -24079.892 | H12: =-'Debt Schedule'!H18 -> -22171.274
B13: Add:Other Income | C13: ='Profit & Loss'!C11 -> 28962 | D13: =C13 -> 28962 | E13: =D13 -> 28962 | F13: =E13 -> 28962 | G13: =F13 -> 28962 | H13: =G13 -> 28962
B14: Profit Before Tax | C14: =SUM(C11:C13) -> 123162 | D14: =SUM(D11:D13) -> 135207.12 | E14: =SUM(E11:E13) -> 144820.14 | F14: =SUM(F11:F13) -> 155483.29 | G14: =SUM(G11:G13) -> 166160.01 | H14: =SUM(H11:H13) -> 176746.73
B15: Less: Tax | C15: =-SUM('Profit & Loss'!C28:C29) -> -27552 | D15: =-Assumptions!C10*'Projected Profit and Loss'!D14 -> -31259.162 | E15: =-Assumptions!D10*'Projected Profit and Loss'!E14 -> -33481.64 | F15: =-Assumptions!E10*'Projected Profit and Loss'!F14 -> -35946.901 | G15: =-Assumptions!F10*'Projected Profit and Loss'!G14 -> -38415.303 | H15: =-Assumptions!G10*'Projected Profit and Loss'!H14 -> -40862.895
B16: Profit After Tax | C16: =SUM(C14:C15) -> 95610 | D16: =SUM(D14:D15) -> 103947.96 | E16: =SUM(E14:E15) -> 111338.5 | F16: =SUM(F14:F15) -> 119536.39 | G16: =SUM(G14:G15) -> 127744.71 | H16: =SUM(H14:H15) -> 135883.83
B19: Capex | C19: =-'Cash Flow Statement'!B27 -> 122916 | D19: =D6*Assumptions!C14 -> 155365.36 | E19: =E6*Assumptions!D14 -> 152555.73 | F19: =F6*Assumptions!E14 -> 148145.43 | G19: =G6*Assumptions!F14 -> 142109.59 | H19: =H6*Assumptions!G14 -> 134454.15

Sheet DCF Valuation
A1: Reliance Industries Limited — DCF Valuation
A2: (₹ in crore unless stated) — built on Projected IS / BS, FY27E-FY31E explicit period
A4: SECTION 1: Unlevered Free Cash Flow
A5: Particulars | C5: FY27E | D5: FY28E | E5: FY29E | F5: FY30E | G5: FY31E
A6: EBIT | C6: ='Projected Profit and Loss'!D11 -> 133877.87 | D6: ='Projected Profit and Loss'!E11 -> 143136.94 | E6: ='Projected Profit and Loss'!F11 -> 152303.6 | F6: ='Projected Profit and Loss'!G11 -> 161277.9 | G6: ='Projected Profit and Loss'!H11 -> 169956
A7: Less: Tax on EBIT (EBIT x Tax Rate) | C7: =-C6*Assumptions!C10 -> -30951.844 | D7: =-D6*Assumptions!D10 -> -33092.492 | E7: =-E6*Assumptions!E10 -> -35211.774 | F7: =-F6*Assumptions!F10 -> -37286.585 | G7: =-G6*Assumptions!G10 -> -39292.915
A8: EBIT x (1 - Tax Rate) [NOPAT] | C8: =C6+C7 -> 102926.02 | D8: =D6+D7 -> 110044.45 | E8: =E6+E7 -> 117091.82 | F8: =F6+F7 -> 123991.32 | G8: =G6+G7 -> 130663.09
A9: Add: D&A | C9: =-'Projected Profit and Loss'!D10 -> 60906.645 | D9: =-'Projected Profit and Loss'!E10 -> 65780.975 | E9: =-'Projected Profit and Loss'!F10 -> 70686.198 | F9: =-'Projected Profit and Loss'!G10 -> 75572.399 | G9: =-'Projected Profit and Loss'!H10 -> 80386.153
A10: Less: Capex | C10: =-'Projected Profit and Loss'!D19 -> -155365.36 | D10: =-'Projected Profit and Loss'!E19 -> -152555.73 | E10: =-'Projected Profit and Loss'!F19 -> -148145.43 | F10: =-'Projected Profit and Loss'!G19 -> -142109.59 | G10: =-'Projected Profit and Loss'!H19 -> -134454.15
A11: Less: Increase in Net Working Capital | C11: =-(('Projected Balance Sheet'!D13+'Projected Balance Sheet'!D10-'Projected Balance Sheet'!D45)-('Projected Balance Sheet'!C10+'Projected Balance Sheet'!C13-'Projected Balance Sheet'!C45)) -> -5305.1111 | D11: =-(('Projected Balance Sheet'!E13+'Projected Balance Sheet'!E10-'Projected Balance Sheet'!E45)-('Projected Balance Sheet'!D10+'Projected Balance Sheet'!D13-'Projected Balance Sheet'!D45)) -> 19447.695 | E11: =-(('Projected Balance Sheet'!F13+'Projected Balance Sheet'!F10-'Projected Balance Sheet'!F45)-('Projected Balance Sheet'!E10+'Projected Balance Sheet'!E13-'Projected Balance Sheet'!E45)) -> 22284.565 | F11: =-(('Projected Balance Sheet'!G13+'Projected Balance Sheet'!G10-'Projected Balance Sheet'!G45)-('Projected Balance Sheet'!F10+'Projected Balance Sheet'!F13-'Projected Balance Sheet'!F45)) -> -1582.3664 | G11: =-(('Projected Balance Sheet'!H13+'Projected Balance Sheet'!H10-'Projected Balance Sheet'!H45)-('Projected Balance Sheet'!G10+'Projected Balance Sheet'!G13-'Projected Balance Sheet'!G45)) -> -1506.125
A12: Note: Net Working Capital = Receivables + Inventory − Payables; the change year-over-year is deducted.
A13: Unlevered Free Cash Flow (FCFF) | C13: =SUM(C6:C11) -> 106088.22 | D13: =SUM(D6:D11) -> 152761.83 | E13: =SUM(E6:E11) -> 179008.98 | F13: =SUM(F6:F11) -> 179863.08 | G13: =SUM(G6:G11) -> 205752.06
A16: SECTION 2: WACC Calculation
A18: Risk-Free Rate (Rf) — India 10Y G-Sec | B18: 0.0685 | C18: [Source: India 10Y G-Sec, ~6.85%, mid-June 2026]
A19: Beta — RIL | B19: 0.94 | C19: [Source: RIL stock beta, recent]
A20: Equity Risk Premium (ERP) — India | B20: 0.065 | C20: [Standard India ERP estimate, ~6-7%]
A21: Cost of Equity = Rf + Beta x ERP | B21: =B18+B19*B20 -> 0.1296
A23: Interest Rate on Debt (from Assumptions) | B23: =Assumptions!B15 -> 0.07319421
A24: Tax Rate (from Assumptions) | B24: =Assumptions!B10 -> 0.23119463
A25: Cost of Debt (post-tax) = Interest Rate x (1 - Tax Rate) | B25: =B23*(1-B24) -> 0.056272101
A27: Market Cap (Equity Value) | B27: 1772085 | C27: [Source: RIL market cap, ~23 June 2026]
A28: Total Debt (Book Value, FY26A) | B28: ='Debt Schedule'!C12 -> 374421
A29: Total Capital (Market Cap + Debt) | B29: =B27+B28 -> 2146506
A30: Equity Weight | B30: =B27/B29 -> 0.82556722
A31: Debt Weight | B31: =B28/B29 -> 0.17443278
A33: WACC = (Equity Weight x Cost of Equity) + (Debt Weight x Cost of Debt) | B33: =B30*B21+B31*B25 -> 0.11680921
A36: SECTION 3: Terminal Value
A38: FY31E Unlevered FCF | B38: =G13 -> 205752.06
A39: Terminal Growth Rate (from Assumptions) | B39: =Assumptions!H6 -> 0.045
A40: Terminal Value = FY31E FCF x (1+g) / (WACC - g) | B40: =(B38*(1+B39))/(B33-B39) -> 2994196.6
A41: Note: Terminal value requires WACC > terminal growth rate; here 11.7% vs 4.5%.
A44: SECTION 4: Discounting to Present Value
A45: Particulars | C45: FY27E | D45: FY28E | E45: FY29E | F45: FY30E | G45: FY31E
A46: Year Number (n) | C46: 1 | D46: 2 | E46: 3 | F46: 4 | G46: 5
A47: Discount Factor = 1/(1+WACC)^n | C47: =1/(1+$B$33)^C46 -> 0.89540809 | D47: =1/(1+$B$33)^D46 -> 0.80175564 | E47: =1/(1+$B$33)^E46 -> 0.71789849 | F47: =1/(1+$B$33)^F46 -> 0.64281211 | G47: =1/(1+$B$33)^G46 -> 0.57557916
A48: Unlevered FCF (from Section 1) | C48: =C13 -> 106088.22 | D48: =D13 -> 152761.83 | E48: =E13 -> 179008.98 | F48: =F13 -> 179863.08 | G48: =G13 -> 205752.06
A49: PV of FCF | C49: =C48*C47 -> 94992.249 | D49: =D48*D47 -> 122477.66 | E49: =E48*E47 -> 128510.28 | F49: =F48*F47 -> 115618.17 | G49: =G48*G47 -> 118426.6
A51: PV of Terminal Value (discount at FY31E factor) | C51: =B40*G47 -> 1723397.2
A52: Sum of PV of Explicit FCF (FY27E-FY31E) | C52: =SUM(C49:G49) -> 580024.95
A53: Enterprise Value = Sum of PV of FCF + PV of Terminal Value | C53: =C51+C52 -> 2303422.1
...

Sheet Comps Valuation
A1: Reliance Industries Limited — Comparable Company Analysis (EV/EBITDA)
A2: Cross-check against DCF — note: RIL is a diversified conglomerate (O2C, Retail, Telecom), so a single blended peer multiple is an approximation, not a precise read
A4: Company | B4: Segment Relevance | C4: EV/EBITDA | D4: Source
A5: ONGC | B5: Oil & Gas / E&P (O2C proxy) | C5: 5 | D5: GuruFocus / Screener, ~Jun 2026
A6: Bharti Airtel | B6: Telecom (Jio proxy) | C6: 9.5 | D6: Screener / Finbox, ~Jun 2026
A7: RIL (own current multiple) | B7: Reference — RIL's actual trading multiple | C7: 15.65 | D7: GuruFocus, TTM Sep-25 EV/EBITDA
A9: Peer Average EV/EBITDA (ONGC + Bharti Airtel, excl. RIL self-reference) | C9: =AVERAGE(C5:C6) -> 7.25
A11: Applied to RIL FY27E EBITDA
A12: FY27E EBIT (from Projected P&L) | B12: ='Projected Profit and Loss'!D11 -> 133877.87
A13: FY27E D&A (from Projected P&L) | B13: =-'Projected Profit and Loss'!D10 -> 60906.645
A14: FY27E EBITDA = EBIT + D&A | B14: =B12+B13 -> 194784.51
A16: Implied EV (Peer Avg Multiple x FY27E EBITDA) | B16: =C9*B14 -> 1412187.7
A17: Implied EV (RIL Own Multiple x FY27E EBITDA) — sanity reference | B17: =C7*B14 -> 3048377.6
A19: Bridge to Equity Value (using Peer Average multiple)
A20: Implied EV | B20: =B16 -> 1412187.7
A21: Less: Total Debt (FY26A) | B21: =-'Debt Schedule'!C12 -> -374421
A22: Add: Cash and Cash Equivalents (FY26A) | B22: ='Balance Sheet'!C27 -> 145977
A23: Implied Equity Value | B23: =SUM(B20:B22) -> 1183743.7
A25: Shares Outstanding (crore) | B25: ='DCF Valuation'!C63 -> 1353.2473
A26: Implied Share Price via Comps (Rs) | B26: =B23/B25 -> 874.74307
A28: Cross-Check Summary
A29: DCF Implied Price | B29: ='DCF Valuation'!C64 -> 1533.3326
A30: Comps Implied Price (Peer Avg) | B30: =B26 -> 874.74307
A31: Current Market Price | B31: ='DCF Valuation'!C66 -> 1369
